Workbook

Sheet Cover
A1: CITY OF SEALY
A2: ESD #2 Development-Scenario Fiscal Model
A3: Council edition · June 2026 · Independent planning analysis (not a certified forecast) · Prepared by Councilmember Bobby Necker, Place 1
A5: 30-YEAR 1.5% SALES-TAX POOL · current INPUTS scenario
A6: =Results!F10 -> 98603635
A8: How to use this model
A9: 1. On TYPICAL INPUTS: set a scenario Active = Yes, choose a Development Type, enter a quantity (and lot size / gross-up for subdivisions).
A10: 2. Read the RESULTS block on that same page — the 1.5% sales-tax pool and the City / EDC / ESD shares by horizon.
A11: 3. Enter your City / ESD split at the top of Typical Inputs; it is yours to set and everything updates live.
A12: 4. Advanced Inputs holds every deeper assumption; Capital Items the infrastructure detail; Sources & Assumptions the citations.
A14: Go to
A15: ▸ Typical Inputs — set scenario, read results
A16: ▸ Advanced Inputs — all assumptions
A17: ▸ Results — full sales-tax & fiscal detail
A18: ▸ Capital Items — infrastructure detail

Sheet Typical Inputs
A1: TYPICAL INPUTS
A2: Set your split and scenarios here — results update live below. Everything for a meeting on one page.
A4: 1 · SALES-TAX ALLOCATION (City + ESD must total 100%)
A5: City General Fund share of pool
A6: EDC retention (% of City share) | C6: 0
A7: ESD #2 share of pool
A8: Sales-tax pool rate | C8: 0.015
A9: Split check (City + ESD) | C9: =C5+C7 -> 0 | D9: ← must equal 100%
A11: 2 · DEVELOPMENT SCENARIOS (Active = Yes, pick a type, enter quantity)
A12: Development Type | B12: Active? | C12: Quantity | D12: Lot size (ac/unit) | E12: Gross-up % (non-lot) | F12: Final Acres (computed)
A13: Big-Box / Anchor Retail | B13: Yes | C13: 10 | F13: ='Advanced Inputs'!J55 -> 10
A14: Retail Center / Strip | B14: No | C14: 10 | F14: ='Advanced Inputs'!J56 -> 10
A15: Office / Business Park | B15: No | C15: 10 | F15: ='Advanced Inputs'!J57 -> 10
A16: Light Industrial / Flex | B16: No | C16: 15 | F16: ='Advanced Inputs'!J58 -> 15
A17: Mixed-Use Pad / Vertical | B17: No | C17: 10 | F17: ='Advanced Inputs'!J59 -> 10
A18: Gas / Convenience Store | B18: No | C18: 1.5 | F18: ='Advanced Inputs'!J60 -> 1.5
A19: Large Travel Center (C-store) | B19: No | C19: 15 | F19: ='Advanced Inputs'!J61 -> 15
A20: Fast Food / QSR | B20: No | C20: 1 | F20: ='Advanced Inputs'!J62 -> 1
A21: Restaurant (Full-Service) | B21: No | C21: 1.5 | F21: ='Advanced Inputs'!J63 -> 1.5
A22: Grocery / Supermarket | B22: No | C22: 4 | F22: ='Advanced Inputs'!J64 -> 4
A23: Auto Parts / Service | B23: No | C23: 1.5 | F23: ='Advanced Inputs'!J65 -> 1.5
A24: Car Wash | B24: No | C24: 1 | F24: ='Advanced Inputs'!J66 -> 1
A25: Single-Family Subdivision | B25: Yes | C25: 100 | D25: 0.125 | E25: 0.5 | F25: ='Advanced Inputs'!J67 -> 18.75
A26: Single-Family Urban / Patio | B26: No | C26: 100 | E26: 0.5 | F26: ='Advanced Inputs'!J68 -> 27
A27: Townhome / Condo | B27: No | C27: 250 | E27: 0.5 | F27: ='Advanced Inputs'!J69 -> 37.5
A28: Multifamily Apartments | B28: No | C28: 250 | E28: 0.5 | F28: ='Advanced Inputs'!J70 -> 15
A29: Hotel | B29: No | C29: 100 | F29: ='Advanced Inputs'!J71 -> 2
A30: Manufacturing | B30: No | C30: 20 | F30: ='Advanced Inputs'!J72 -> 20
A31: Industrial / Logistics | B31: No | C31: 40 | F31: ='Advanced Inputs'!J73 -> 40
A32: Civic / Institutional | B32: No | C32: 10 | F32: ='Advanced Inputs'!J74 -> 10
A33: Parks / Open Space | B33: No | C33: 10 | F33: ='Advanced Inputs'!J75 -> 10
A34: Vacant / Holding Land | B34: No | C34: 10 | F34: ='Advanced Inputs'!J76 -> 10
A35: Gross-up % adds non-lot land (streets, detention, open space) for infrastructure sizing only — value & tax stay per-home. Sealy newer subdivisions (Westward Pointe / BSR): ~0.24-ac lots, ~50% gross-up (~2.6 homes per gross acre).
A36: 3 · RESULTS (live from your scenario — by horizon)
B37: 5-Year | C37: 10-Year | D37: 15-Year | E37: 20-Year | F37: 30-Year
A38: 1.5% sales-tax pool (the pie) | B38: =Results!B10 -> 1558728.3 | C38: =Results!C10 -> 10949246 | D38: =Results!D10 -> 23810531 | E38: =Results!E10 -> 41426083 | F38: =Results!F10 -> 98603635
A39: → City General Fund | B39: =Results!B11 -> 0 | C39: =Results!C11 -> 0 | D39: =Results!D11 -> 0 | E39: =Results!E11 -> 0 | F39: =Results!F11 -> 0
A40: → Sealy EDC (carve-out) | B40: =Results!B12 -> 0 | C40: =Results!C12 -> 0 | D40: =Results!D12 -> 0 | E40: =Results!E12 -> 0 | F40: =Results!F12 -> 0
A41: → ESD #2 share | B41: =Results!B13 -> 0 | C41: =Results!C13 -> 0 | D41: =Results!D13 -> 0 | E41: =Results!E13 -> 0 | F41: =Results!F13 -> 0
A43: City NET fiscal position | B43: =Results!B25 -> -3183421.2 | C43: =Results!C25 -> -8116362.7 | D43: =Results!D25 -> -12914101 | E43: =Results!E25 -> -17489434 | F43: =Results!F25 -> -17285751
...

Sheet Advanced Inputs
A1: INPUTS
A2: All user-editable assumptions · edit the "Your input" column · Section F holds the development scenarios
A4: Assumption | B4: Recommended | D4: Your input
A5: A. ALLOCATION & TAX RATES
A6: City General Fund share of sales-tax pool | B6: (enter) | D6: ='Typical Inputs'!C5 -> 0
A7: EDC retention of sales tax (%) | B7: 0 | D7: ='Typical Inputs'!C6 -> 0 | E7: EDC basis: | F7: 1 | G7: =IF($F$7="","",IF($F$7=2,IF($D$7>$D$6,"WARNING: EDC % ("&TEXT($D$7,"0%")&") exceeds City pool share ("&TEXT($D$6,"0%")&") - General Fund goes NEGATIVE",""),IF($D$7>1,"WARNING: EDC % over 100% - General Fund negative",""))) | H7: (1 = % of City share | 2 = % of total 1.5% pool)
A8: ESD #2 share of sales-tax pool | B8: (enter) | D8: ='Typical Inputs'!C7 -> 0
A9: Sales-tax pool rate | B9: 0.015 | D9: ='Typical Inputs'!C8 -> 0.015
A10: City property tax rate (per $1 AV) | B10: 0.0037731 | D10: 0.0037731
A11: ESD #2 property tax rate (per $1 AV) | B11: 0.000931 | D11: 0.000931
A12: B. GROWTH & FINANCIAL
A13: Sealy current population | B13: 7937 | D13: 7937
A14: Population CAGR | B14: 0.032 | D14: 0.032
A15: Current annual sales-tax pool ($) | B15: 3700000 | D15: 3700000
A16: Sales-tax pool CAGR | B16: 0.065 | D16: 0.065
A17: Property AV growth CAGR | B17: 0.06 | D17: 0.06
A18: Annexation capture rate | B18: 0.8 | D18: 0.8
A19: General opex inflation CAGR | B19: 0.025 | D19: 0.025
A20: Capital construction inflation CAGR | B20: 0.045 | D20: 0.045
A21: City reserve % (opex+capital basis) | B21: 0.025 | D21: 0.025
A22: ESD reserve % (opex+capital basis) | B22: 0.025 | D22: 0.025
A23: Reserve basis includes capital? (1=Yes,0=No) | B23: 1 | D23: 0
A24: Property tax collection rate | B24: 0.95 | D24: 1
A25: C. RESIDENT ONLINE / DELIVERY USE-TAX
A26: SFR occupancy rate | B26: 0.95 | D26: 0.95
A27: MFR occupancy rate | B27: 0.92 | D27: 0.92
A28: SFR household size | B28: 2.7 | D28: 2.7
A29: MFR household size | B29: 2.1 | D29: 2.1
A30: Online spend per occupied household ($) | B30: 6000 | D30: 6000
A31: Taxable share of online spending | B31: 0.7 | D31: 0.7
A32: Local address capture factor | B32: 0.75 | D32: 0.75
A33: Online spend growth (CAGR) | B33: 0.04 | D33: 0.04
A34: Include online use-tax? (1=Yes,0=No) | B34: 1 | D34: 1
A36: D. EXEMPTION ADJUSTMENT — effective taxable-value factor (edit % cells; factor = 1 − sum)
A37: Category | B37: Homestead% | D37: DisVet% | E37: Freeport% | F37: Pollution% | G37: Other% | H37: Haircut | I37: Factor | J37: ESD Hmstd% | K37: ESD Ov65% | L37: ESD DVet% | M37: ESD Free% | N37: ESD Poll% | O37: ESD Other% | P37: ESD Haircut | Q37: ESD Factor
A38: Residential | B38: 0 | C38: 0.005 | D38: 0.015 | E38: 0 | F38: 0 | G38: 0 | H38: =SUM(B38:G38) -> 0.02 | I38: =MAX(0,1-H38) -> 0.98 | J38: 0.015 | K38: 0.005 | L38: 0.015 | M38: 0 | N38: 0 | O38: 0 | P38: =SUM(J38:O38) -> 0.035 | Q38: =MAX(0,1-P38) -> 0.965
A39: Commercial | B39: 0 | C39: 0 | D39: 0 | E39: 0 | F39: 0 | G39: 0.01 | H39: =SUM(B39:G39) -> 0.01 | I39: =MAX(0,1-H39) -> 0.99 | J39: 0 | K39: 0 | L39: 0 | M39: 0 | N39: 0 | O39: 0.01 | P39: =SUM(J39:O39) -> 0.01 | Q39: =MAX(0,1-P39) -> 0.99
A40: Industrial | B40: 0 | C40: 0 | D40: 0 | E40: 0.05 | F40: 0.02 | G40: 0.01 | H40: =SUM(B40:G40) -> 0.08 | I40: =MAX(0,1-H40) -> 0.92 | J40: 0 | K40: 0 | L40: 0 | M40: 0.05 | N40: 0.02 | O40: 0.01 | P40: =SUM(J40:O40) -> 0.08 | Q40: =MAX(0,1-P40) -> 0.92
A41: Civic | B41: 0 | C41: 0 | D41: 0 | E41: 0 | F41: 0 | G41: 1 | H41: =SUM(B41:G41) -> 1 | I41: =MAX(0,1-H41) -> 0 | J41: 0 | K41: 0 | L41: 0 | M41: 0 | N41: 0 | O41: 1 | P41: =SUM(J41:O41) -> 1 | Q41: =MAX(0,1-P41) -> 0
A42: Vacant | B42: 0 | C42: 0 | D42: 0 | E42: 0 | F42: 0 | G42: 0 | H42: =SUM(B42:G42) -> 0 | I42: =MAX(0,1-H42) -> 1 | J42: 0 | K42: 0 | L42: 0 | M42: 0 | N42: 0 | O42: 0 | P42: =SUM(J42:O42) -> 0 | Q42: =MAX(0,1-P42) -> 1
...

Sheet Capital Items
A1: CAPITAL ITEMS
A2: Infrastructure & service capital (supporting detail) · auto-sized by development · feeds the Fiscal Context section of RESULTS
A3: Item | B3: Entity | C3: Driver (what triggers qty) | D3: Unit | E3: Typical factor | F3: 5-year auto qty | G3: 10-year auto qty | H3: 15-year auto qty | I3: 20-year auto qty | J3: 30-year auto qty | K3: Manual qty +/- | L3: Cumulative quantity (at buildout) | M3: Unit cost ($) | N3: Unit cost override | O3: Manual Total Cost Override | P3: Total cost (today's $) | Q3: Who pays | R3: Include in net? | S3: How it's paid | T3: Year incurred (build yr) | U3: Debt term (yrs) | V3: Debt rate | W3: Annual Debt Service | X3: City 5-year impact | Y3: City 10-year impact | Z3: City 15-year impact | AA3: City 20-year impact | AB3: City 30-year impact | AC3: ESD 5-year impact | AD3: ESD 10-year impact | AE3: ESD 15-year impact | AF3: ESD 20-year impact | AG3: ESD 30-year impact | AH3: Source / Note | AI3: DS @5yr-qty | AJ3: DS @10yr-qty | AK3: DS @15yr-qty | AL3: DS @20yr-qty | AM3: DS @30yr-qty
A4: 12-inch water main, transmission | B4: City | C4: captured acres | D4: linear ft | E4: 60 LF/ac | F4: ='03_Multi_Horizon_Results'!$B$5*'12_Takeoff_Assumptions'!$B$3 -> 1725 | G4: ='03_Multi_Horizon_Results'!$C$5*'12_Takeoff_Assumptions'!$B$3 -> 1725 | H4: ='03_Multi_Horizon_Results'!$D$5*'12_Takeoff_Assumptions'!$B$3 -> 1725 | I4: ='03_Multi_Horizon_Results'!$E$5*'12_Takeoff_Assumptions'!$B$3 -> 1725 | J4: ='03_Multi_Horizon_Results'!$F$5*'12_Takeoff_Assumptions'!$B$3 -> 1725 | L4: =MAX(0,N(G4)+N(K4)) -> 1725 | M4: 600 | P4: =IFERROR(IF(O4<>"",O4,L4*IF(N4<>"",N4,M4)),0) -> 1035000 | Q4: City | R4: Yes | S4: Debt service | T4: 1 | U4: 20 | V4: 0.045 | W4: =IFERROR(IF(AND(R4="Yes",S4="Debt service",U4>0),IF(V4=0,P4/U4,P4*V4/(1-(1+V4)^(-U4))),0),0) -> 79566.809 | X4: =IFERROR(IF(OR(R4<>"Yes",Q4<>"City"),0,IF(S4="Cash capital",IF(T4<=5,IF(O4<>"",O4,MAX(0,N(F4)+N(K4))*IF(N4<>"",N4,M4)),0),IF(S4="Debt service",IF(T4>5,0,AI4*MAX(0,MIN(5-T4+1,U4))),IF(OR(S4="Annual O&M",S4="Maintenance-only"),IF(T4>5,0,IF(O4<>"",O4,MAX(0,N(F4)+N(K4))*IF(N4<>"",N4,M4))*MAX(0,5-T4+1)),0)))),0) -> 397834.05 | Y4: =IFERROR(IF(OR(R4<>"Yes",Q4<>"City"),0,IF(S4="Cash capital",IF(T4<=10,IF(O4<>"",O4,MAX(0,N(G4)+N(K4))*IF(N4<>"",N4,M4)),0),IF(S4="Debt service",IF(T4>10,0,AJ4*MAX(0,MIN(10-T4+1,U4))),IF(OR(S4="Annual O&M",S4="Maintenance-only"),IF(T4>10,0,IF(O4<>"",O4,MAX(0,N(G4)+N(K4))*IF(N4<>"",N4,M4))*MAX(0,10-T4+1)),0)))),0) -> 795668.09 | Z4: =IFERROR(IF(OR(R4<>"Yes",Q4<>"City"),0,IF(S4="Cash capital",IF(T4<=15,IF(O4<>"",O4,MAX(0,N(H4)+N(K4))*IF(N4<>"",N4,M4)),0),IF(S4="Debt service",IF(T4>15,0,AK4*MAX(0,MIN(15-T4+1,U4))),IF(OR(S4="Annual O&M",S4="Maintenance-only"),IF(T4>15,0,IF(O4<>"",O4,MAX(0,N(H4)+N(K4))*IF(N4<>"",N4,M4))*MAX(0,15-T4+1)),0)))),0) -> 1193502.1 | AA4: =IFERROR(IF(OR(R4<>"Yes",Q4<>"City"),0,IF(S4="Cash capital",IF(T4<=20,IF(O4<>"",O4,MAX(0,N(I4)+N(K4))*IF(N4<>"",N4,M4)),0),IF(S4="Debt service",IF(T4>20,0,AL4*MAX(0,MIN(20-T4+1,U4))),IF(OR(S4="Annual O&M",S4="Maintenance-only"),IF(T4>20,0,IF(O4<>"",O4,MAX(0,N(I4)+N(K4))*IF(N4<>"",N4,M4))*MAX(0,20-T4+1)),0)))),0) -> 1591336.2 | AB4: =IFERROR(IF(OR(R4<>"Yes",Q4<>"City"),0,IF(S4="Cash capital",IF(T4<=30,IF(O4<>"",O4,MAX(0,N(J4)+N(K4))*IF(N4<>"",N4,M4)),0),IF(S4="Debt service",IF(T4>30,0,AM4*MAX(0,MIN(30-T4+1,U4))),IF(OR(S4="Annual O&M",S4="Maintenance-only"),IF(T4>30,0,IF(O4<>"",O4,MAX(0,N(J4)+N(K4))*IF(N4<>"",N4,M4))*MAX(0,30-T4+1)),0)))),0) -> 1591336.2 | AC4: =IFERROR(IF(OR(R4<>"Yes",Q4<>"ESD"),0,IF(S4="Cash capital",IF(T4<=5,IF(O4<>"",O4,MAX(0,N(F4)+N(K4))*IF(N4<>"",N4,M4)),0),IF(S4="Debt service",IF(T4>5,0,AI4*MAX(0,MIN(5-T4+1,U4))),IF(OR(S4="Annual O&M",S4="Maintenance-only"),IF(T4>5,0,IF(O4<>"",O4,MAX(0,N(F4)+N(K4))*IF(N4<>"",N4,M4))*MAX(0,5-T4+1)),0)))),0) -> 0 | AD4: =IFERROR(IF(OR(R4<>"Yes",Q4<>"ESD"),0,IF(S4="Cash capital",IF(T4<=10,IF(O4<>"",O4,MAX(0,N(G4)+N(K4))*IF(N4<>"",N4,M4)),0),IF(S4="Debt service",IF(T4>10,0,AJ4*MAX(0,MIN(10-T4+1,U4))),IF(OR(S4="Annual O&M",S4="Maintenance-only"),IF(T4>10,0,IF(O4<>"",O4,MAX(0,N(G4)+N(K4))*IF(N4<>"",N4,M4))*MAX(0,10-T4+1)),0)))),0) -> 0 | AE4: =IFERROR(IF(OR(R4<>"Yes",Q4<>"ESD"),0,IF(S4="Cash capital",IF(T4<=15,IF(O4<>"",O4,MAX(0,N(H4)+N(K4))*IF(N4<>"",N4,M4)),0),IF(S4="Debt service",IF(T4>15,0,AK4*MAX(0,MIN(15-T4+1,U4))),IF(OR(S4="Annual O&M",S4="Maintenance-only"),IF(T4>15,0,IF(O4<>"",O4,MAX(0,N(H4)+N(K4))*IF(N4<>"",N4,M4))*MAX(0,15-T4+1)),0)))),0) -> 0 | AF4: =IFERROR(IF(OR(R4<>"Yes",Q4<>"ESD"),0,IF(S4="Cash capital",IF(T4<=20,IF(O4<>"",O4,MAX(0,N(I4)+N(K4))*IF(N4<>"",N4,M4)),0),IF(S4="Debt service",IF(T4>20,0,AL4*MAX(0,MIN(20-T4+1,U4))),IF(OR(S4="Annual O&M",S4="Maintenance-only"),IF(T4>20,0,IF(O4<>"",O4,MAX(0,N(I4)+N(K4))*IF(N4<>"",N4,M4))*MAX(0,20-T4+1)),0)))),0) -> 0 | AG4: =IFERROR(IF(OR(R4<>"Yes",Q4<>"ESD"),0,IF(S4="Cash capital",IF(T4<=30,IF(O4<>"",O4,MAX(0,N(J4)+N(K4))*IF(N4<>"",N4,M4)),0),IF(S4="Debt service",IF(T4>30,0,AM4*MAX(0,MIN(30-T4+1,U4))),IF(OR(S4="Annual O&M",S4="Maintenance-only"),IF(T4>30,0,IF(O4<>"",O4,MAX(0,N(J4)+N(K4))*IF(N4<>"",N4,M4))*MAX(0,30-T4+1)),0)))),0) -> 0 | AH4: Planning allowance for trunk/looping needs; engineer/Public Works validation required. | Takeoff factor: 60 LF per developed acre; confidence Low; validate w/ Engineer/Public Works. | AI4: =IFERROR(IF(U4>0,IF(O4<>"",O4,MAX(0,N(F4)+N(K4))*IF(N4<>"",N4,M4))*IF(V4=0,1/U4,V4/(1-(1+V4)^(-U4))),0),0) -> 79566.809 | AJ4: =IFERROR(IF(U4>0,IF(O4<>"",O4,MAX(0,N(G4)+N(K4))*IF(N4<>"",N4,M4))*IF(V4=0,1/U4,V4/(1-(1+V4)^(-U4))),0),0) -> 79566.809 | AK4: =IFERROR(IF(U4>0,IF(O4<>"",O4,MAX(0,N(H4)+N(K4))*IF(N4<>"",N4,M4))*IF(V4=0,1/U4,V4/(1-(1+V4)^(-U4))),0),0) -> 79566.809 | AL4: =IFERROR(IF(U4>0,IF(O4<>"",O4,MAX(0,N(I4)+N(K4))*IF(N4<>"",N4,M4))*IF(V4=0,1/U4,V4/(1-(1+V4)^(-U4))),0),0) -> 79566.809 | AM4: =IFERROR(IF(U4>0,IF(O4<>"",O4,MAX(0,N(J4)+N(K4))*IF(N4<>"",N4,M4))*IF(V4=0,1/U4,V4/(1-(1+V4)^(-U4))),0),0) -> 79566.809
A5: 8-inch water main, distribution | B5: City | C5: captured acres | D5: linear ft | E5: 400 LF/ac | F5: ='03_Multi_Horizon_Results'!$B$5*'12_Takeoff_Assumptions'!$B$2 -> 11500 | G5: ='03_Multi_Horizon_Results'!$C$5*'12_Takeoff_Assumptions'!$B$2 -> 11500 | H5: ='03_Multi_Horizon_Results'!$D$5*'12_Takeoff_Assumptions'!$B$2 -> 11500 | I5: ='03_Multi_Horizon_Results'!$E$5*'12_Takeoff_Assumptions'!$B$2 -> 11500 | J5: ='03_Multi_Horizon_Results'!$F$5*'12_Takeoff_Assumptions'!$B$2 -> 11500 | L5: =MAX(0,N(G5)+N(K5)) -> 11500 | M5: 250 | P5: =IFERROR(IF(O5<>"",O5,L5*IF(N5<>"",N5,M5)),0) -> 2875000 | Q5: City | R5: Yes | S5: Debt service | T5: 1 | U5: 20 | V5: 0.045 | W5: =IFERROR(IF(AND(R5="Yes",S5="Debt service",U5>0),IF(V5=0,P5/U5,P5*V5/(1-(1+V5)^(-U5))),0),0) -> 221018.91 | X5: =IFERROR(IF(OR(R5<>"Yes",Q5<>"City"),0,IF(S5="Cash capital",IF(T5<=5,IF(O5<>"",O5,MAX(0,N(F5)+N(K5))*IF(N5<>"",N5,M5)),0),IF(S5="Debt service",IF(T5>5,0,AI5*MAX(0,MIN(5-T5+1,U5))),IF(OR(S5="Annual O&M",S5="Maintenance-only"),IF(T5>5,0,IF(O5<>"",O5,MAX(0,N(F5)+N(K5))*IF(N5<>"",N5,M5))*MAX(0,5-T5+1)),0)))),0) -> 1105094.6 | Y5: =IFERROR(IF(OR(R5<>"Yes",Q5<>"City"),0,IF(S5="Cash capital",IF(T5<=10,IF(O5<>"",O5,MAX(0,N(G5)+N(K5))*IF(N5<>"",N5,M5)),0),IF(S5="Debt service",IF(T5>10,0,AJ5*MAX(0,MIN(10-T5+1,U5))),IF(OR(S5="Annual O&M",S5="Maintenance-only"),IF(T5>10,0,IF(O5<>"",O5,MAX(0,N(G5)+N(K5))*IF(N5<>"",N5,M5))*MAX(0,10-T5+1)),0)))),0) -> 2210189.1 | Z5: =IFERROR(IF(OR(R5<>"Yes",Q5<>"City"),0,IF(S5="Cash capital",IF(T5<=15,IF(O5<>"",O5,MAX(0,N(H5)+N(K5))*IF(N5<>"",N5,M5)),0),IF(S5="Debt service",IF(T5>15,0,AK5*MAX(0,MIN(15-T5+1,U5))),IF(OR(S5="Annual O&M",S5="Maintenance-only"),IF(T5>15,0,IF(O5<>"",O5,MAX(0,N(H5)+N(K5))*IF(N5<>"",N5,M5))*MAX(0,15-T5+1)),0)))),0) -> 3315283.7 | AA5: =IFERROR(IF(OR(R5<>"Yes",Q5<>"City"),0,IF(S5="Cash capital",IF(T5<=20,IF(O5<>"",O5,MAX(0,N(I5)+N(K5))*IF(N5<>"",N5,M5)),0),IF(S5="Debt service",IF(T5>20,0,AL5*MAX(0,MIN(20-T5+1,U5))),IF(OR(S5="Annual O&M",S5="Maintenance-only"),IF(T5>20,0,IF(O5<>"",O5,MAX(0,N(I5)+N(K5))*IF(N5<>"",N5,M5))*MAX(0,20-T5+1)),0)))),0) -> 4420378.3 | AB5: =IFERROR(IF(OR(R5<>"Yes",Q5<>"City"),0,IF(S5="Cash capital",IF(T5<=30,IF(O5<>"",O5,MAX(0,N(J5)+N(K5))*IF(N5<>"",N5,M5)),0),IF(S5="Debt service",IF(T5>30,0,AM5*MAX(0,MIN(30-T5+1,U5))),IF(OR(S5="Annual O&M",S5="Maintenance-only"),IF(T5>30,0,IF(O5<>"",O5,MAX(0,N(J5)+N(K5))*IF(N5<>"",N5,M5))*MAX(0,30-T5+1)),0)))),0) -> 4420378.3 | AC5: =IFERROR(IF(OR(R5<>"Yes",Q5<>"ESD"),0,IF(S5="Cash capital",IF(T5<=5,IF(O5<>"",O5,MAX(0,N(F5)+N(K5))*IF(N5<>"",N5,M5)),0),IF(S5="Debt service",IF(T5>5,0,AI5*MAX(0,MIN(5-T5+1,U5))),IF(OR(S5="Annual O&M",S5="Maintenance-only"),IF(T5>5,0,IF(O5<>"",O5,MAX(0,N(F5)+N(K5))*IF(N5<>"",N5,M5))*MAX(0,5-T5+1)),0)))),0) -> 0 | AD5: =IFERROR(IF(OR(R5<>"Yes",Q5<>"ESD"),0,IF(S5="Cash capital",IF(T5<=10,IF(O5<>"",O5,MAX(0,N(G5)+N(K5))*IF(N5<>"",N5,M5)),0),IF(S5="Debt service",IF(T5>10,0,AJ5*MAX(0,MIN(10-T5+1,U5))),IF(OR(S5="Annual O&M",S5="Maintenance-only"),IF(T5>10,0,IF(O5<>"",O5,MAX(0,N(G5)+N(K5))*IF(N5<>"",N5,M5))*MAX(0,10-T5+1)),0)))),0) -> 0 | AE5: =IFERROR(IF(OR(R5<>"Yes",Q5<>"ESD"),0,IF(S5="Cash capital",IF(T5<=15,IF(O5<>"",O5,MAX(0,N(H5)+N(K5))*IF(N5<>"",N5,M5)),0),IF(S5="Debt service",IF(T5>15,0,AK5*MAX(0,MIN(15-T5+1,U5))),IF(OR(S5="Annual O&M",S5="Maintenance-only"),IF(T5>15,0,IF(O5<>"",O5,MAX(0,N(H5)+N(K5))*IF(N5<>"",N5,M5))*MAX(0,15-T5+1)),0)))),0) -> 0 | AF5: =IFERROR(IF(OR(R5<>"Yes",Q5<>"ESD"),0,IF(S5="Cash capital",IF(T5<=20,IF(O5<>"",O5,MAX(0,N(I5)+N(K5))*IF(N5<>"",N5,M5)),0),IF(S5="Debt service",IF(T5>20,0,AL5*MAX(0,MIN(20-T5+1,U5))),IF(OR(S5="Annual O&M",S5="Maintenance-only"),IF(T5>20,0,IF(O5<>"",O5,MAX(0,N(I5)+N(K5))*IF(N5<>"",N5,M5))*MAX(0,20-T5+1)),0)))),0) -> 0 | AG5: =IFERROR(IF(OR(R5<>"Yes",Q5<>"ESD"),0,IF(S5="Cash capital",IF(T5<=30,IF(O5<>"",O5,MAX(0,N(J5)+N(K5))*IF(N5<>"",N5,M5)),0),IF(S5="Debt service",IF(T5>30,0,AM5*MAX(0,MIN(30-T5+1,U5))),IF(OR(S5="Annual O&M",S5="Maintenance-only"),IF(T5>30,0,IF(O5<>"",O5,MAX(0,N(J5)+N(K5))*IF(N5<>"",N5,M5))*MAX(0,30-T5+1)),0)))),0) -> 0 | AH5: Subdivision/internal water distribution planning allowance; actual plat should override. | Takeoff factor: 400 LF per developed acre; confidence Low; validate w/ Engineer/Public Works. | AI5: =IFERROR(IF(U5>0,IF(O5<>"",O5,MAX(0,N(F5)+N(K5))*IF(N5<>"",N5,M5))*IF(V5=0,1/U5,V5/(1-(1+V5)^(-U5))),0),0) -> 221018.91 | AJ5: =IFERROR(IF(U5>0,IF(O5<>"",O5,MAX(0,N(G5)+N(K5))*IF(N5<>"",N5,M5))*IF(V5=0,1/U5,V5/(1-(1+V5)^(-U5))),0),0) -> 221018.91 | AK5: =IFERROR(IF(U5>0,IF(O5<>"",O5,MAX(0,N(H5)+N(K5))*IF(N5<>"",N5,M5))*IF(V5=0,1/U5,V5/(1-(1+V5)^(-U5))),0),0) -> 221018.91 | AL5: =IFERROR(IF(U5>0,IF(O5<>"",O5,MAX(0,N(I5)+N(K5))*IF(N5<>"",N5,M5))*IF(V5=0,1/U5,V5/(1-(1+V5)^(-U5))),0),0) -> 221018.91 | AM5: =IFERROR(IF(U5>0,IF(O5<>"",O5,MAX(0,N(J5)+N(K5))*IF(N5<>"",N5,M5))*IF(V5=0,1/U5,V5/(1-(1+V5)^(-U5))),0),0) -> 221018.91
A6: Fire hydrants | B6: City | C6: water distribution LF | D6: each | E6: hydrant spacing 500 LF | F6: =IFERROR(ROUNDUP(('03_Multi_Horizon_Results'!$B$5*'12_Takeoff_Assumptions'!$B$2)/'12_Takeoff_Assumptions'!$B$9,0),0) -> 23 | G6: =IFERROR(ROUNDUP(('03_Multi_Horizon_Results'!$C$5*'12_Takeoff_Assumptions'!$B$2)/'12_Takeoff_Assumptions'!$B$9,0),0) -> 23 | H6: =IFERROR(ROUNDUP(('03_Multi_Horizon_Results'!$D$5*'12_Takeoff_Assumptions'!$B$2)/'12_Takeoff_Assumptions'!$B$9,0),0) -> 23 | I6: =IFERROR(ROUNDUP(('03_Multi_Horizon_Results'!$E$5*'12_Takeoff_Assumptions'!$B$2)/'12_Takeoff_Assumptions'!$B$9,0),0) -> 23 | J6: =IFERROR(ROUNDUP(('03_Multi_Horizon_Results'!$F$5*'12_Takeoff_Assumptions'!$B$2)/'12_Takeoff_Assumptions'!$B$9,0),0) -> 23 | L6: =MAX(0,N(G6)+N(K6)) -> 23 | M6: 7500 | P6: =IFERROR(IF(O6<>"",O6,L6*IF(N6<>"",N6,M6)),0) -> 172500 | Q6: City | R6: Yes | S6: Debt service | T6: 1 | U6: 20 | V6: 0.045 | W6: =IFERROR(IF(AND(R6="Yes",S6="Debt service",U6>0),IF(V6=0,P6/U6,P6*V6/(1-(1+V6)^(-U6))),0),0) -> 13261.135 | X6: =IFERROR(IF(OR(R6<>"Yes",Q6<>"City"),0,IF(S6="Cash capital",IF(T6<=5,IF(O6<>"",O6,MAX(0,N(F6)+N(K6))*IF(N6<>"",N6,M6)),0),IF(S6="Debt service",IF(T6>5,0,AI6*MAX(0,MIN(5-T6+1,U6))),IF(OR(S6="Annual O&M",S6="Maintenance-only"),IF(T6>5,0,IF(O6<>"",O6,MAX(0,N(F6)+N(K6))*IF(N6<>"",N6,M6))*MAX(0,5-T6+1)),0)))),0) -> 66305.674 | Y6: =IFERROR(IF(OR(R6<>"Yes",Q6<>"City"),0,IF(S6="Cash capital",IF(T6<=10,IF(O6<>"",O6,MAX(0,N(G6)+N(K6))*IF(N6<>"",N6,M6)),0),IF(S6="Debt service",IF(T6>10,0,AJ6*MAX(0,MIN(10-T6+1,U6))),IF(OR(S6="Annual O&M",S6="Maintenance-only"),IF(T6>10,0,IF(O6<>"",O6,MAX(0,N(G6)+N(K6))*IF(N6<>"",N6,M6))*MAX(0,10-T6+1)),0)))),0) -> 132611.35 | Z6: =IFERROR(IF(OR(R6<>"Yes",Q6<>"City"),0,IF(S6="Cash capital",IF(T6<=15,IF(O6<>"",O6,MAX(0,N(H6)+N(K6))*IF(N6<>"",N6,M6)),0),IF(S6="Debt service",IF(T6>15,0,AK6*MAX(0,MIN(15-T6+1,U6))),IF(OR(S6="Annual O&M",S6="Maintenance-only"),IF(T6>15,0,IF(O6<>"",O6,MAX(0,N(H6)+N(K6))*IF(N6<>"",N6,M6))*MAX(0,15-T6+1)),0)))),0) -> 198917.02 | AA6: =IFERROR(IF(OR(R6<>"Yes",Q6<>"City"),0,IF(S6="Cash capital",IF(T6<=20,IF(O6<>"",O6,MAX(0,N(I6)+N(K6))*IF(N6<>"",N6,M6)),0),IF(S6="Debt service",IF(T6>20,0,AL6*MAX(0,MIN(20-T6+1,U6))),IF(OR(S6="Annual O&M",S6="Maintenance-only"),IF(T6>20,0,IF(O6<>"",O6,MAX(0,N(I6)+N(K6))*IF(N6<>"",N6,M6))*MAX(0,20-T6+1)),0)))),0) -> 265222.7 | AB6: =IFERROR(IF(OR(R6<>"Yes",Q6<>"City"),0,IF(S6="Cash capital",IF(T6<=30,IF(O6<>"",O6,MAX(0,N(J6)+N(K6))*IF(N6<>"",N6,M6)),0),IF(S6="Debt service",IF(T6>30,0,AM6*MAX(0,MIN(30-T6+1,U6))),IF(OR(S6="Annual O&M",S6="Maintenance-only"),IF(T6>30,0,IF(O6<>"",O6,MAX(0,N(J6)+N(K6))*IF(N6<>"",N6,M6))*MAX(0,30-T6+1)),0)))),0) -> 265222.7 | AC6: =IFERROR(IF(OR(R6<>"Yes",Q6<>"ESD"),0,IF(S6="Cash capital",IF(T6<=5,IF(O6<>"",O6,MAX(0,N(F6)+N(K6))*IF(N6<>"",N6,M6)),0),IF(S6="Debt service",IF(T6>5,0,AI6*MAX(0,MIN(5-T6+1,U6))),IF(OR(S6="Annual O&M",S6="Maintenance-only"),IF(T6>5,0,IF(O6<>"",O6,MAX(0,N(F6)+N(K6))*IF(N6<>"",N6,M6))*MAX(0,5-T6+1)),0)))),0) -> 0 | AD6: =IFERROR(IF(OR(R6<>"Yes",Q6<>"ESD"),0,IF(S6="Cash capital",IF(T6<=10,IF(O6<>"",O6,MAX(0,N(G6)+N(K6))*IF(N6<>"",N6,M6)),0),IF(S6="Debt service",IF(T6>10,0,AJ6*MAX(0,MIN(10-T6+1,U6))),IF(OR(S6="Annual O&M",S6="Maintenance-only"),IF(T6>10,0,IF(O6<>"",O6,MAX(0,N(G6)+N(K6))*IF(N6<>"",N6,M6))*MAX(0,10-T6+1)),0)))),0) -> 0 | AE6: =IFERROR(IF(OR(R6<>"Yes",Q6<>"ESD"),0,IF(S6="Cash capital",IF(T6<=15,IF(O6<>"",O6,MAX(0,N(H6)+N(K6))*IF(N6<>"",N6,M6)),0),IF(S6="Debt service",IF(T6>15,0,AK6*MAX(0,MIN(15-T6+1,U6))),IF(OR(S6="Annual O&M",S6="Maintenance-only"),IF(T6>15,0,IF(O6<>"",O6,MAX(0,N(H6)+N(K6))*IF(N6<>"",N6,M6))*MAX(0,15-T6+1)),0)))),0) -> 0 | AF6: =IFERROR(IF(OR(R6<>"Yes",Q6<>"ESD"),0,IF(S6="Cash capital",IF(T6<=20,IF(O6<>"",O6,MAX(0,N(I6)+N(K6))*IF(N6<>"",N6,M6)),0),IF(S6="Debt service",IF(T6>20,0,AL6*MAX(0,MIN(20-T6+1,U6))),IF(OR(S6="Annual O&M",S6="Maintenance-only"),IF(T6>20,0,IF(O6<>"",O6,MAX(0,N(I6)+N(K6))*IF(N6<>"",N6,M6))*MAX(0,20-T6+1)),0)))),0) -> 0 | AG6: =IFERROR(IF(OR(R6<>"Yes",Q6<>"ESD"),0,IF(S6="Cash capital",IF(T6<=30,IF(O6<>"",O6,MAX(0,N(J6)+N(K6))*IF(N6<>"",N6,M6)),0),IF(S6="Debt service",IF(T6>30,0,AM6*MAX(0,MIN(30-T6+1,U6))),IF(OR(S6="Annual O&M",S6="Maintenance-only"),IF(T6>30,0,IF(O6<>"",O6,MAX(0,N(J6)+N(K6))*IF(N6<>"",N6,M6))*MAX(0,30-T6+1)),0)))),0) -> 0 | AH6: Hydrant count from distribution LF / spacing; verify fire code and utility standards. | Takeoff factor: 500 LF between hydrants; confidence Medium; validate w/ Fire/Public Works. | AI6: =IFERROR(IF(U6>0,IF(O6<>"",O6,MAX(0,N(F6)+N(K6))*IF(N6<>"",N6,M6))*IF(V6=0,1/U6,V6/(1-(1+V6)^(-U6))),0),0) -> 13261.135 | AJ6: =IFERROR(IF(U6>0,IF(O6<>"",O6,MAX(0,N(G6)+N(K6))*IF(N6<>"",N6,M6))*IF(V6=0,1/U6,V6/(1-(1+V6)^(-U6))),0),0) -> 13261.135 | AK6: =IFERROR(IF(U6>0,IF(O6<>"",O6,MAX(0,N(H6)+N(K6))*IF(N6<>"",N6,M6))*IF(V6=0,1/U6,V6/(1-(1+V6)^(-U6))),0),0) -> 13261.135 | AL6: =IFERROR(IF(U6>0,IF(O6<>"",O6,MAX(0,N(I6)+N(K6))*IF(N6<>"",N6,M6))*IF(V6=0,1/U6,V6/(1-(1+V6)^(-U6))),0),0) -> 13261.135 | AM6: =IFERROR(IF(U6>0,IF(O6<>"",O6,MAX(0,N(J6)+N(K6))*IF(N6<>"",N6,M6))*IF(V6=0,1/U6,V6/(1-(1+V6)^(-U6))),0),0) -> 13261.135
A7: Water wells, 1,500 gpm | B7: City | C7: water demand MGD | D7: each | E7: threshold 0.50 MGD | F7: =IF((('03_Multi_Horizon_Results'!$B$22/'Advanced Inputs'!$D$50)*'12_Takeoff_Assumptions'!$B$13/1000000)>'12_Takeoff_Assumptions'!$B$16,ROUNDUP((('03_Multi_Horizon_Results'!$B$22/'Advanced Inputs'!$D$50)*'12_Takeoff_Assumptions'!$B$13/1000000)/'12_Takeoff_Assumptions'!$B$16,0),0) -> 0 | G7: =IF((('03_Multi_Horizon_Results'!$C$22/'Advanced Inputs'!$D$50)*'12_Takeoff_Assumptions'!$B$13/1000000)>'12_Takeoff_Assumptions'!$B$16,ROUNDUP((('03_Multi_Horizon_Results'!$C$22/'Advanced Inputs'!$D$50)*'12_Takeoff_Assumptions'!$B$13/1000000)/'12_Takeoff_Assumptions'!$B$16,0),0) -> 0 | H7: =IF((('03_Multi_Horizon_Results'!$D$22/'Advanced Inputs'!$D$50)*'12_Takeoff_Assumptions'!$B$13/1000000)>'12_Takeoff_Assumptions'!$B$16,ROUNDUP((('03_Multi_Horizon_Results'!$D$22/'Advanced Inputs'!$D$50)*'12_Takeoff_Assumptions'!$B$13/1000000)/'12_Takeoff_Assumptions'!$B$16,0),0) -> 0 | I7: =IF((('03_Multi_Horizon_Results'!$E$22/'Advanced Inputs'!$D$50)*'12_Takeoff_Assumptions'!$B$13/1000000)>'12_Takeoff_Assumptions'!$B$16,ROUNDUP((('03_Multi_Horizon_Results'!$E$22/'Advanced Inputs'!$D$50)*'12_Takeoff_Assumptions'!$B$13/1000000)/'12_Takeoff_Assumptions'!$B$16,0),0) -> 0 | J7: =IF((('03_Multi_Horizon_Results'!$F$22/'Advanced Inputs'!$D$50)*'12_Takeoff_Assumptions'!$B$13/1000000)>'12_Takeoff_Assumptions'!$B$16,ROUNDUP((('03_Multi_Horizon_Results'!$F$22/'Advanced Inputs'!$D$50)*'12_Takeoff_Assumptions'!$B$13/1000000)/'12_Takeoff_Assumptions'!$B$16,0),0) -> 0 | L7: =MAX(0,N(G7)+N(K7)) -> 0 | M7: 1500000 | P7: =IFERROR(IF(O7<>"",O7,L7*IF(N7<>"",N7,M7)),0) -> 0 | Q7: City | R7: Yes | S7: Debt service | T7: 1 | U7: 20 | V7: 0.045 | W7: =IFERROR(IF(AND(R7="Yes",S7="Debt service",U7>0),IF(V7=0,P7/U7,P7*V7/(1-(1+V7)^(-U7))),0),0) -> 0 | X7: =IFERROR(IF(OR(R7<>"Yes",Q7<>"City"),0,IF(S7="Cash capital",IF(T7<=5,IF(O7<>"",O7,MAX(0,N(F7)+N(K7))*IF(N7<>"",N7,M7)),0),IF(S7="Debt service",IF(T7>5,0,AI7*MAX(0,MIN(5-T7+1,U7))),IF(OR(S7="Annual O&M",S7="Maintenance-only"),IF(T7>5,0,IF(O7<>"",O7,MAX(0,N(F7)+N(K7))*IF(N7<>"",N7,M7))*MAX(0,5-T7+1)),0)))),0) -> 0 | Y7: =IFERROR(IF(OR(R7<>"Yes",Q7<>"City"),0,IF(S7="Cash capital",IF(T7<=10,IF(O7<>"",O7,MAX(0,N(G7)+N(K7))*IF(N7<>"",N7,M7)),0),IF(S7="Debt service",IF(T7>10,0,AJ7*MAX(0,MIN(10-T7+1,U7))),IF(OR(S7="Annual O&M",S7="Maintenance-only"),IF(T7>10,0,IF(O7<>"",O7,MAX(0,N(G7)+N(K7))*IF(N7<>"",N7,M7))*MAX(0,10-T7+1)),0)))),0) -> 0 | Z7: =IFERROR(IF(OR(R7<>"Yes",Q7<>"City"),0,IF(S7="Cash capital",IF(T7<=15,IF(O7<>"",O7,MAX(0,N(H7)+N(K7))*IF(N7<>"",N7,M7)),0),IF(S7="Debt service",IF(T7>15,0,AK7*MAX(0,MIN(15-T7+1,U7))),IF(OR(S7="Annual O&M",S7="Maintenance-only"),IF(T7>15,0,IF(O7<>"",O7,MAX(0,N(H7)+N(K7))*IF(N7<>"",N7,M7))*MAX(0,15-T7+1)),0)))),0) -> 0 | AA7: =IFERROR(IF(OR(R7<>"Yes",Q7<>"City"),0,IF(S7="Cash capital",IF(T7<=20,IF(O7<>"",O7,MAX(0,N(I7)+N(K7))*IF(N7<>"",N7,M7)),0),IF(S7="Debt service",IF(T7>20,0,AL7*MAX(0,MIN(20-T7+1,U7))),IF(OR(S7="Annual O&M",S7="Maintenance-only"),IF(T7>20,0,IF(O7<>"",O7,MAX(0,N(I7)+N(K7))*IF(N7<>"",N7,M7))*MAX(0,20-T7+1)),0)))),0) -> 0 | AB7: =IFERROR(IF(OR(R7<>"Yes",Q7<>"City"),0,IF(S7="Cash capital",IF(T7<=30,IF(O7<>"",O7,MAX(0,N(J7)+N(K7))*IF(N7<>"",N7,M7)),0),IF(S7="Debt service",IF(T7>30,0,AM7*MAX(0,MIN(30-T7+1,U7))),IF(OR(S7="Annual O&M",S7="Maintenance-only"),IF(T7>30,0,IF(O7<>"",O7,MAX(0,N(J7)+N(K7))*IF(N7<>"",N7,M7))*MAX(0,30-T7+1)),0)))),0) -> 0 | AC7: =IFERROR(IF(OR(R7<>"Yes",Q7<>"ESD"),0,IF(S7="Cash capital",IF(T7<=5,IF(O7<>"",O7,MAX(0,N(F7)+N(K7))*IF(N7<>"",N7,M7)),0),IF(S7="Debt service",IF(T7>5,0,AI7*MAX(0,MIN(5-T7+1,U7))),IF(OR(S7="Annual O&M",S7="Maintenance-only"),IF(T7>5,0,IF(O7<>"",O7,MAX(0,N(F7)+N(K7))*IF(N7<>"",N7,M7))*MAX(0,5-T7+1)),0)))),0) -> 0 | AD7: =IFERROR(IF(OR(R7<>"Yes",Q7<>"ESD"),0,IF(S7="Cash capital",IF(T7<=10,IF(O7<>"",O7,MAX(0,N(G7)+N(K7))*IF(N7<>"",N7,M7)),0),IF(S7="Debt service",IF(T7>10,0,AJ7*MAX(0,MIN(10-T7+1,U7))),IF(OR(S7="Annual O&M",S7="Maintenance-only"),IF(T7>10,0,IF(O7<>"",O7,MAX(0,N(G7)+N(K7))*IF(N7<>"",N7,M7))*MAX(0,10-T7+1)),0)))),0) -> 0 | AE7: =IFERROR(IF(OR(R7<>"Yes",Q7<>"ESD"),0,IF(S7="Cash capital",IF(T7<=15,IF(O7<>"",O7,MAX(0,N(H7)+N(K7))*IF(N7<>"",N7,M7)),0),IF(S7="Debt service",IF(T7>15,0,AK7*MAX(0,MIN(15-T7+1,U7))),IF(OR(S7="Annual O&M",S7="Maintenance-only"),IF(T7>15,0,IF(O7<>"",O7,MAX(0,N(H7)+N(K7))*IF(N7<>"",N7,M7))*MAX(0,15-T7+1)),0)))),0) -> 0 | AF7: =IFERROR(IF(OR(R7<>"Yes",Q7<>"ESD"),0,IF(S7="Cash capital",IF(T7<=20,IF(O7<>"",O7,MAX(0,N(I7)+N(K7))*IF(N7<>"",N7,M7)),0),IF(S7="Debt service",IF(T7>20,0,AL7*MAX(0,MIN(20-T7+1,U7))),IF(OR(S7="Annual O&M",S7="Maintenance-only"),IF(T7>20,0,IF(O7<>"",O7,MAX(0,N(I7)+N(K7))*IF(N7<>"",N7,M7))*MAX(0,20-T7+1)),0)))),0) -> 0 | AG7: =IFERROR(IF(OR(R7<>"Yes",Q7<>"ESD"),0,IF(S7="Cash capital",IF(T7<=30,IF(O7<>"",O7,MAX(0,N(J7)+N(K7))*IF(N7<>"",N7,M7)),0),IF(S7="Debt service",IF(T7>30,0,AM7*MAX(0,MIN(30-T7+1,U7))),IF(OR(S7="Annual O&M",S7="Maintenance-only"),IF(T7>30,0,IF(O7<>"",O7,MAX(0,N(J7)+N(K7))*IF(N7<>"",N7,M7))*MAX(0,30-T7+1)),0)))),0) -> 0 | AH7: Demand-based planning trigger; validate with water master plan and TCEQ capacity review. | Takeoff factor: 0.5 MGD demand; confidence Low; validate w/ Engineer/Public Works. | AI7: =IFERROR(IF(U7>0,IF(O7<>"",O7,MAX(0,N(F7)+N(K7))*IF(N7<>"",N7,M7))*IF(V7=0,1/U7,V7/(1-(1+V7)^(-U7))),0),0) -> 0 | AJ7: =IFERROR(IF(U7>0,IF(O7<>"",O7,MAX(0,N(G7)+N(K7))*IF(N7<>"",N7,M7))*IF(V7=0,1/U7,V7/(1-(1+V7)^(-U7))),0),0) -> 0 | AK7: =IFERROR(IF(U7>0,IF(O7<>"",O7,MAX(0,N(H7)+N(K7))*IF(N7<>"",N7,M7))*IF(V7=0,1/U7,V7/(1-(1+V7)^(-U7))),0),0) -> 0 | AL7: =IFERROR(IF(U7>0,IF(O7<>"",O7,MAX(0,N(I7)+N(K7))*IF(N7<>"",N7,M7))*IF(V7=0,1/U7,V7/(1-(1+V7)^(-U7))),0),0) -> 0 | AM7: =IFERROR(IF(U7>0,IF(O7<>"",O7,MAX(0,N(J7)+N(K7))*IF(N7<>"",N7,M7))*IF(V7=0,1/U7,V7/(1-(1+V7)^(-U7))),0),0) -> 0
A8: Gravity sewer main, 10-inch | B8: City | C8: captured acres | D8: linear ft | E8: 300 LF/ac | F8: ='03_Multi_Horizon_Results'!$B$5*'12_Takeoff_Assumptions'!$B$4 -> 8625 | G8: ='03_Multi_Horizon_Results'!$C$5*'12_Takeoff_Assumptions'!$B$4 -> 8625 | H8: ='03_Multi_Horizon_Results'!$D$5*'12_Takeoff_Assumptions'!$B$4 -> 8625 | I8: ='03_Multi_Horizon_Results'!$E$5*'12_Takeoff_Assumptions'!$B$4 -> 8625 | J8: ='03_Multi_Horizon_Results'!$F$5*'12_Takeoff_Assumptions'!$B$4 -> 8625 | L8: =MAX(0,N(G8)+N(K8)) -> 8625 | M8: 325 | P8: =IFERROR(IF(O8<>"",O8,L8*IF(N8<>"",N8,M8)),0) -> 2803125 | Q8: City | R8: Yes | S8: Debt service | T8: 1 | U8: 20 | V8: 0.045 | W8: =IFERROR(IF(AND(R8="Yes",S8="Debt service",U8>0),IF(V8=0,P8/U8,P8*V8/(1-(1+V8)^(-U8))),0),0) -> 215493.44 | X8: =IFERROR(IF(OR(R8<>"Yes",Q8<>"City"),0,IF(S8="Cash capital",IF(T8<=5,IF(O8<>"",O8,MAX(0,N(F8)+N(K8))*IF(N8<>"",N8,M8)),0),IF(S8="Debt service",IF(T8>5,0,AI8*MAX(0,MIN(5-T8+1,U8))),IF(OR(S8="Annual O&M",S8="Maintenance-only"),IF(T8>5,0,IF(O8<>"",O8,MAX(0,N(F8)+N(K8))*IF(N8<>"",N8,M8))*MAX(0,5-T8+1)),0)))),0) -> 1077467.2 | Y8: =IFERROR(IF(OR(R8<>"Yes",Q8<>"City"),0,IF(S8="Cash capital",IF(T8<=10,IF(O8<>"",O8,MAX(0,N(G8)+N(K8))*IF(N8<>"",N8,M8)),0),IF(S8="Debt service",IF(T8>10,0,AJ8*MAX(0,MIN(10-T8+1,U8))),IF(OR(S8="Annual O&M",S8="Maintenance-only"),IF(T8>10,0,IF(O8<>"",O8,MAX(0,N(G8)+N(K8))*IF(N8<>"",N8,M8))*MAX(0,10-T8+1)),0)))),0) -> 2154934.4 | Z8: =IFERROR(IF(OR(R8<>"Yes",Q8<>"City"),0,IF(S8="Cash capital",IF(T8<=15,IF(O8<>"",O8,MAX(0,N(H8)+N(K8))*IF(N8<>"",N8,M8)),0),IF(S8="Debt service",IF(T8>15,0,AK8*MAX(0,MIN(15-T8+1,U8))),IF(OR(S8="Annual O&M",S8="Maintenance-only"),IF(T8>15,0,IF(O8<>"",O8,MAX(0,N(H8)+N(K8))*IF(N8<>"",N8,M8))*MAX(0,15-T8+1)),0)))),0) -> 3232401.6 | AA8: =IFERROR(IF(OR(R8<>"Yes",Q8<>"City"),0,IF(S8="Cash capital",IF(T8<=20,IF(O8<>"",O8,MAX(0,N(I8)+N(K8))*IF(N8<>"",N8,M8)),0),IF(S8="Debt service",IF(T8>20,0,AL8*MAX(0,MIN(20-T8+1,U8))),IF(OR(S8="Annual O&M",S8="Maintenance-only"),IF(T8>20,0,IF(O8<>"",O8,MAX(0,N(I8)+N(K8))*IF(N8<>"",N8,M8))*MAX(0,20-T8+1)),0)))),0) -> 4309868.8 | AB8: =IFERROR(IF(OR(R8<>"Yes",Q8<>"City"),0,IF(S8="Cash capital",IF(T8<=30,IF(O8<>"",O8,MAX(0,N(J8)+N(K8))*IF(N8<>"",N8,M8)),0),IF(S8="Debt service",IF(T8>30,0,AM8*MAX(0,MIN(30-T8+1,U8))),IF(OR(S8="Annual O&M",S8="Maintenance-only"),IF(T8>30,0,IF(O8<>"",O8,MAX(0,N(J8)+N(K8))*IF(N8<>"",N8,M8))*MAX(0,30-T8+1)),0)))),0) -> 4309868.8 | AC8: =IFERROR(IF(OR(R8<>"Yes",Q8<>"ESD"),0,IF(S8="Cash capital",IF(T8<=5,IF(O8<>"",O8,MAX(0,N(F8)+N(K8))*IF(N8<>"",N8,M8)),0),IF(S8="Debt service",IF(T8>5,0,AI8*MAX(0,MIN(5-T8+1,U8))),IF(OR(S8="Annual O&M",S8="Maintenance-only"),IF(T8>5,0,IF(O8<>"",O8,MAX(0,N(F8)+N(K8))*IF(N8<>"",N8,M8))*MAX(0,5-T8+1)),0)))),0) -> 0 | AD8: =IFERROR(IF(OR(R8<>"Yes",Q8<>"ESD"),0,IF(S8="Cash capital",IF(T8<=10,IF(O8<>"",O8,MAX(0,N(G8)+N(K8))*IF(N8<>"",N8,M8)),0),IF(S8="Debt service",IF(T8>10,0,AJ8*MAX(0,MIN(10-T8+1,U8))),IF(OR(S8="Annual O&M",S8="Maintenance-only"),IF(T8>10,0,IF(O8<>"",O8,MAX(0,N(G8)+N(K8))*IF(N8<>"",N8,M8))*MAX(0,10-T8+1)),0)))),0) -> 0 | AE8: =IFERROR(IF(OR(R8<>"Yes",Q8<>"ESD"),0,IF(S8="Cash capital",IF(T8<=15,IF(O8<>"",O8,MAX(0,N(H8)+N(K8))*IF(N8<>"",N8,M8)),0),IF(S8="Debt service",IF(T8>15,0,AK8*MAX(0,MIN(15-T8+1,U8))),IF(OR(S8="Annual O&M",S8="Maintenance-only"),IF(T8>15,0,IF(O8<>"",O8,MAX(0,N(H8)+N(K8))*IF(N8<>"",N8,M8))*MAX(0,15-T8+1)),0)))),0) -> 0 | AF8: =IFERROR(IF(OR(R8<>"Yes",Q8<>"ESD"),0,IF(S8="Cash capital",IF(T8<=20,IF(O8<>"",O8,MAX(0,N(I8)+N(K8))*IF(N8<>"",N8,M8)),0),IF(S8="Debt service",IF(T8>20,0,AL8*MAX(0,MIN(20-T8+1,U8))),IF(OR(S8="Annual O&M",S8="Maintenance-only"),IF(T8>20,0,IF(O8<>"",O8,MAX(0,N(I8)+N(K8))*IF(N8<>"",N8,M8))*MAX(0,20-T8+1)),0)))),0) -> 0 | AG8: =IFERROR(IF(OR(R8<>"Yes",Q8<>"ESD"),0,IF(S8="Cash capital",IF(T8<=30,IF(O8<>"",O8,MAX(0,N(J8)+N(K8))*IF(N8<>"",N8,M8)),0),IF(S8="Debt service",IF(T8>30,0,AM8*MAX(0,MIN(30-T8+1,U8))),IF(OR(S8="Annual O&M",S8="Maintenance-only"),IF(T8>30,0,IF(O8<>"",O8,MAX(0,N(J8)+N(K8))*IF(N8<>"",N8,M8))*MAX(0,30-T8+1)),0)))),0) -> 0 | AH8: Gravity sewer planning allowance; actual basin/topography should override. | Takeoff factor: 300 LF per developed acre; confidence Low; validate w/ Engineer/Public Works. | AI8: =IFERROR(IF(U8>0,IF(O8<>"",O8,MAX(0,N(F8)+N(K8))*IF(N8<>"",N8,M8))*IF(V8=0,1/U8,V8/(1-(1+V8)^(-U8))),0),0) -> 215493.44 | AJ8: =IFERROR(IF(U8>0,IF(O8<>"",O8,MAX(0,N(G8)+N(K8))*IF(N8<>"",N8,M8))*IF(V8=0,1/U8,V8/(1-(1+V8)^(-U8))),0),0) -> 215493.44 | AK8: =IFERROR(IF(U8>0,IF(O8<>"",O8,MAX(0,N(H8)+N(K8))*IF(N8<>"",N8,M8))*IF(V8=0,1/U8,V8/(1-(1+V8)^(-U8))),0),0) -> 215493.44 | AL8: =IFERROR(IF(U8>0,IF(O8<>"",O8,MAX(0,N(I8)+N(K8))*IF(N8<>"",N8,M8))*IF(V8=0,1/U8,V8/(1-(1+V8)^(-U8))),0),0) -> 215493.44 | AM8: =IFERROR(IF(U8>0,IF(O8<>"",O8,MAX(0,N(J8)+N(K8))*IF(N8<>"",N8,M8))*IF(V8=0,1/U8,V8/(1-(1+V8)^(-U8))),0),0) -> 215493.44
A9: Force main | B9: City | C9: captured acres | D9: linear ft | E9: 40 LF/ac | F9: ='03_Multi_Horizon_Results'!$B$5*'12_Takeoff_Assumptions'!$B$5 -> 1150 | G9: ='03_Multi_Horizon_Results'!$C$5*'12_Takeoff_Assumptions'!$B$5 -> 1150 | H9: ='03_Multi_Horizon_Results'!$D$5*'12_Takeoff_Assumptions'!$B$5 -> 1150 | I9: ='03_Multi_Horizon_Results'!$E$5*'12_Takeoff_Assumptions'!$B$5 -> 1150 | J9: ='03_Multi_Horizon_Results'!$F$5*'12_Takeoff_Assumptions'!$B$5 -> 1150 | L9: =MAX(0,N(G9)+N(K9)) -> 1150 | M9: 225 | P9: =IFERROR(IF(O9<>"",O9,L9*IF(N9<>"",N9,M9)),0) -> 258750 | Q9: City | R9: Yes | S9: Debt service | T9: 1 | U9: 20 | V9: 0.045 | W9: =IFERROR(IF(AND(R9="Yes",S9="Debt service",U9>0),IF(V9=0,P9/U9,P9*V9/(1-(1+V9)^(-U9))),0),0) -> 19891.702 | X9: =IFERROR(IF(OR(R9<>"Yes",Q9<>"City"),0,IF(S9="Cash capital",IF(T9<=5,IF(O9<>"",O9,MAX(0,N(F9)+N(K9))*IF(N9<>"",N9,M9)),0),IF(S9="Debt service",IF(T9>5,0,AI9*MAX(0,MIN(5-T9+1,U9))),IF(OR(S9="Annual O&M",S9="Maintenance-only"),IF(T9>5,0,IF(O9<>"",O9,MAX(0,N(F9)+N(K9))*IF(N9<>"",N9,M9))*MAX(0,5-T9+1)),0)))),0) -> 99458.512 | Y9: =IFERROR(IF(OR(R9<>"Yes",Q9<>"City"),0,IF(S9="Cash capital",IF(T9<=10,IF(O9<>"",O9,MAX(0,N(G9)+N(K9))*IF(N9<>"",N9,M9)),0),IF(S9="Debt service",IF(T9>10,0,AJ9*MAX(0,MIN(10-T9+1,U9))),IF(OR(S9="Annual O&M",S9="Maintenance-only"),IF(T9>10,0,IF(O9<>"",O9,MAX(0,N(G9)+N(K9))*IF(N9<>"",N9,M9))*MAX(0,10-T9+1)),0)))),0) -> 198917.02 | Z9: =IFERROR(IF(OR(R9<>"Yes",Q9<>"City"),0,IF(S9="Cash capital",IF(T9<=15,IF(O9<>"",O9,MAX(0,N(H9)+N(K9))*IF(N9<>"",N9,M9)),0),IF(S9="Debt service",IF(T9>15,0,AK9*MAX(0,MIN(15-T9+1,U9))),IF(OR(S9="Annual O&M",S9="Maintenance-only"),IF(T9>15,0,IF(O9<>"",O9,MAX(0,N(H9)+N(K9))*IF(N9<>"",N9,M9))*MAX(0,15-T9+1)),0)))),0) -> 298375.54 | AA9: =IFERROR(IF(OR(R9<>"Yes",Q9<>"City"),0,IF(S9="Cash capital",IF(T9<=20,IF(O9<>"",O9,MAX(0,N(I9)+N(K9))*IF(N9<>"",N9,M9)),0),IF(S9="Debt service",IF(T9>20,0,AL9*MAX(0,MIN(20-T9+1,U9))),IF(OR(S9="Annual O&M",S9="Maintenance-only"),IF(T9>20,0,IF(O9<>"",O9,MAX(0,N(I9)+N(K9))*IF(N9<>"",N9,M9))*MAX(0,20-T9+1)),0)))),0) -> 397834.05 | AB9: =IFERROR(IF(OR(R9<>"Yes",Q9<>"City"),0,IF(S9="Cash capital",IF(T9<=30,IF(O9<>"",O9,MAX(0,N(J9)+N(K9))*IF(N9<>"",N9,M9)),0),IF(S9="Debt service",IF(T9>30,0,AM9*MAX(0,MIN(30-T9+1,U9))),IF(OR(S9="Annual O&M",S9="Maintenance-only"),IF(T9>30,0,IF(O9<>"",O9,MAX(0,N(J9)+N(K9))*IF(N9<>"",N9,M9))*MAX(0,30-T9+1)),0)))),0) -> 397834.05 | AC9: =IFERROR(IF(OR(R9<>"Yes",Q9<>"ESD"),0,IF(S9="Cash capital",IF(T9<=5,IF(O9<>"",O9,MAX(0,N(F9)+N(K9))*IF(N9<>"",N9,M9)),0),IF(S9="Debt service",IF(T9>5,0,AI9*MAX(0,MIN(5-T9+1,U9))),IF(OR(S9="Annual O&M",S9="Maintenance-only"),IF(T9>5,0,IF(O9<>"",O9,MAX(0,N(F9)+N(K9))*IF(N9<>"",N9,M9))*MAX(0,5-T9+1)),0)))),0) -> 0 | AD9: =IFERROR(IF(OR(R9<>"Yes",Q9<>"ESD"),0,IF(S9="Cash capital",IF(T9<=10,IF(O9<>"",O9,MAX(0,N(G9)+N(K9))*IF(N9<>"",N9,M9)),0),IF(S9="Debt service",IF(T9>10,0,AJ9*MAX(0,MIN(10-T9+1,U9))),IF(OR(S9="Annual O&M",S9="Maintenance-only"),IF(T9>10,0,IF(O9<>"",O9,MAX(0,N(G9)+N(K9))*IF(N9<>"",N9,M9))*MAX(0,10-T9+1)),0)))),0) -> 0 | AE9: =IFERROR(IF(OR(R9<>"Yes",Q9<>"ESD"),0,IF(S9="Cash capital",IF(T9<=15,IF(O9<>"",O9,MAX(0,N(H9)+N(K9))*IF(N9<>"",N9,M9)),0),IF(S9="Debt service",IF(T9>15,0,AK9*MAX(0,MIN(15-T9+1,U9))),IF(OR(S9="Annual O&M",S9="Maintenance-only"),IF(T9>15,0,IF(O9<>"",O9,MAX(0,N(H9)+N(K9))*IF(N9<>"",N9,M9))*MAX(0,15-T9+1)),0)))),0) -> 0 | AF9: =IFERROR(IF(OR(R9<>"Yes",Q9<>"ESD"),0,IF(S9="Cash capital",IF(T9<=20,IF(O9<>"",O9,MAX(0,N(I9)+N(K9))*IF(N9<>"",N9,M9)),0),IF(S9="Debt service",IF(T9>20,0,AL9*MAX(0,MIN(20-T9+1,U9))),IF(OR(S9="Annual O&M",S9="Maintenance-only"),IF(T9>20,0,IF(O9<>"",O9,MAX(0,N(I9)+N(K9))*IF(N9<>"",N9,M9))*MAX(0,20-T9+1)),0)))),0) -> 0 | AG9: =IFERROR(IF(OR(R9<>"Yes",Q9<>"ESD"),0,IF(S9="Cash capital",IF(T9<=30,IF(O9<>"",O9,MAX(0,N(J9)+N(K9))*IF(N9<>"",N9,M9)),0),IF(S9="Debt service",IF(T9>30,0,AM9*MAX(0,MIN(30-T9+1,U9))),IF(OR(S9="Annual O&M",S9="Maintenance-only"),IF(T9>30,0,IF(O9<>"",O9,MAX(0,N(J9)+N(K9))*IF(N9<>"",N9,M9))*MAX(0,30-T9+1)),0)))),0) -> 0 | AH9: Force-main planning allowance; actual need depends on lift-station/basin design. | Takeoff factor: 40 LF per developed acre; confidence Low; validate w/ Engineer/Public Works. | AI9: =IFERROR(IF(U9>0,IF(O9<>"",O9,MAX(0,N(F9)+N(K9))*IF(N9<>"",N9,M9))*IF(V9=0,1/U9,V9/(1-(1+V9)^(-U9))),0),0) -> 19891.702 | AJ9: =IFERROR(IF(U9>0,IF(O9<>"",O9,MAX(0,N(G9)+N(K9))*IF(N9<>"",N9,M9))*IF(V9=0,1/U9,V9/(1-(1+V9)^(-U9))),0),0) -> 19891.702 | AK9: =IFERROR(IF(U9>0,IF(O9<>"",O9,MAX(0,N(H9)+N(K9))*IF(N9<>"",N9,M9))*IF(V9=0,1/U9,V9/(1-(1+V9)^(-U9))),0),0) -> 19891.702 | AL9: =IFERROR(IF(U9>0,IF(O9<>"",O9,MAX(0,N(I9)+N(K9))*IF(N9<>"",N9,M9))*IF(V9=0,1/U9,V9/(1-(1+V9)^(-U9))),0),0) -> 19891.702 | AM9: =IFERROR(IF(U9>0,IF(O9<>"",O9,MAX(0,N(J9)+N(K9))*IF(N9<>"",N9,M9))*IF(V9=0,1/U9,V9/(1-(1+V9)^(-U9))),0),0) -> 19891.702
A10: Lift stations | B10: City | C10: sewer demand MGD | D10: each | E10: threshold 0.25 MGD | F10: =IF((('03_Multi_Horizon_Results'!$B$22/'Advanced Inputs'!$D$50)*'12_Takeoff_Assumptions'!$B$14/1000000)>'12_Takeoff_Assumptions'!$B$15,ROUNDUP((('03_Multi_Horizon_Results'!$B$22/'Advanced Inputs'!$D$50)*'12_Takeoff_Assumptions'!$B$14/1000000)/'12_Takeoff_Assumptions'!$B$15,0),0) -> 0 | G10: =IF((('03_Multi_Horizon_Results'!$C$22/'Advanced Inputs'!$D$50)*'12_Takeoff_Assumptions'!$B$14/1000000)>'12_Takeoff_Assumptions'!$B$15,ROUNDUP((('03_Multi_Horizon_Results'!$C$22/'Advanced Inputs'!$D$50)*'12_Takeoff_Assumptions'!$B$14/1000000)/'12_Takeoff_Assumptions'!$B$15,0),0) -> 0 | H10: =IF((('03_Multi_Horizon_Results'!$D$22/'Advanced Inputs'!$D$50)*'12_Takeoff_Assumptions'!$B$14/1000000)>'12_Takeoff_Assumptions'!$B$15,ROUNDUP((('03_Multi_Horizon_Results'!$D$22/'Advanced Inputs'!$D$50)*'12_Takeoff_Assumptions'!$B$14/1000000)/'12_Takeoff_Assumptions'!$B$15,0),0) -> 0 | I10: =IF((('03_Multi_Horizon_Results'!$E$22/'Advanced Inputs'!$D$50)*'12_Takeoff_Assumptions'!$B$14/1000000)>'12_Takeoff_Assumptions'!$B$15,ROUNDUP((('03_Multi_Horizon_Results'!$E$22/'Advanced Inputs'!$D$50)*'12_Takeoff_Assumptions'!$B$14/1000000)/'12_Takeoff_Assumptions'!$B$15,0),0) -> 0 | J10: =IF((('03_Multi_Horizon_Results'!$F$22/'Advanced Inputs'!$D$50)*'12_Takeoff_Assumptions'!$B$14/1000000)>'12_Takeoff_Assumptions'!$B$15,ROUNDUP((('03_Multi_Horizon_Results'!$F$22/'Advanced Inputs'!$D$50)*'12_Takeoff_Assumptions'!$B$14/1000000)/'12_Takeoff_Assumptions'!$B$15,0),0) -> 0 | L10: =MAX(0,N(G10)+N(K10)) -> 0 | M10: 1250000 | P10: =IFERROR(IF(O10<>"",O10,L10*IF(N10<>"",N10,M10)),0) -> 0 | Q10: City | R10: Yes | S10: Debt service | T10: 1 | U10: 20 | V10: 0.045 | W10: =IFERROR(IF(AND(R10="Yes",S10="Debt service",U10>0),IF(V10=0,P10/U10,P10*V10/(1-(1+V10)^(-U10))),0),0) -> 0 | X10: =IFERROR(IF(OR(R10<>"Yes",Q10<>"City"),0,IF(S10="Cash capital",IF(T10<=5,IF(O10<>"",O10,MAX(0,N(F10)+N(K10))*IF(N10<>"",N10,M10)),0),IF(S10="Debt service",IF(T10>5,0,AI10*MAX(0,MIN(5-T10+1,U10))),IF(OR(S10="Annual O&M",S10="Maintenance-only"),IF(T10>5,0,IF(O10<>"",O10,MAX(0,N(F10)+N(K10))*IF(N10<>"",N10,M10))*MAX(0,5-T10+1)),0)))),0) -> 0 | Y10: =IFERROR(IF(OR(R10<>"Yes",Q10<>"City"),0,IF(S10="Cash capital",IF(T10<=10,IF(O10<>"",O10,MAX(0,N(G10)+N(K10))*IF(N10<>"",N10,M10)),0),IF(S10="Debt service",IF(T10>10,0,AJ10*MAX(0,MIN(10-T10+1,U10))),IF(OR(S10="Annual O&M",S10="Maintenance-only"),IF(T10>10,0,IF(O10<>"",O10,MAX(0,N(G10)+N(K10))*IF(N10<>"",N10,M10))*MAX(0,10-T10+1)),0)))),0) -> 0 | Z10: =IFERROR(IF(OR(R10<>"Yes",Q10<>"City"),0,IF(S10="Cash capital",IF(T10<=15,IF(O10<>"",O10,MAX(0,N(H10)+N(K10))*IF(N10<>"",N10,M10)),0),IF(S10="Debt service",IF(T10>15,0,AK10*MAX(0,MIN(15-T10+1,U10))),IF(OR(S10="Annual O&M",S10="Maintenance-only"),IF(T10>15,0,IF(O10<>"",O10,MAX(0,N(H10)+N(K10))*IF(N10<>"",N10,M10))*MAX(0,15-T10+1)),0)))),0) -> 0 | AA10: =IFERROR(IF(OR(R10<>"Yes",Q10<>"City"),0,IF(S10="Cash capital",IF(T10<=20,IF(O10<>"",O10,MAX(0,N(I10)+N(K10))*IF(N10<>"",N10,M10)),0),IF(S10="Debt service",IF(T10>20,0,AL10*MAX(0,MIN(20-T10+1,U10))),IF(OR(S10="Annual O&M",S10="Maintenance-only"),IF(T10>20,0,IF(O10<>"",O10,MAX(0,N(I10)+N(K10))*IF(N10<>"",N10,M10))*MAX(0,20-T10+1)),0)))),0) -> 0 | AB10: =IFERROR(IF(OR(R10<>"Yes",Q10<>"City"),0,IF(S10="Cash capital",IF(T10<=30,IF(O10<>"",O10,MAX(0,N(J10)+N(K10))*IF(N10<>"",N10,M10)),0),IF(S10="Debt service",IF(T10>30,0,AM10*MAX(0,MIN(30-T10+1,U10))),IF(OR(S10="Annual O&M",S10="Maintenance-only"),IF(T10>30,0,IF(O10<>"",O10,MAX(0,N(J10)+N(K10))*IF(N10<>"",N10,M10))*MAX(0,30-T10+1)),0)))),0) -> 0 | AC10: =IFERROR(IF(OR(R10<>"Yes",Q10<>"ESD"),0,IF(S10="Cash capital",IF(T10<=5,IF(O10<>"",O10,MAX(0,N(F10)+N(K10))*IF(N10<>"",N10,M10)),0),IF(S10="Debt service",IF(T10>5,0,AI10*MAX(0,MIN(5-T10+1,U10))),IF(OR(S10="Annual O&M",S10="Maintenance-only"),IF(T10>5,0,IF(O10<>"",O10,MAX(0,N(F10)+N(K10))*IF(N10<>"",N10,M10))*MAX(0,5-T10+1)),0)))),0) -> 0 | AD10: =IFERROR(IF(OR(R10<>"Yes",Q10<>"ESD"),0,IF(S10="Cash capital",IF(T10<=10,IF(O10<>"",O10,MAX(0,N(G10)+N(K10))*IF(N10<>"",N10,M10)),0),IF(S10="Debt service",IF(T10>10,0,AJ10*MAX(0,MIN(10-T10+1,U10))),IF(OR(S10="Annual O&M",S10="Maintenance-only"),IF(T10>10,0,IF(O10<>"",O10,MAX(0,N(G10)+N(K10))*IF(N10<>"",N10,M10))*MAX(0,10-T10+1)),0)))),0) -> 0 | AE10: =IFERROR(IF(OR(R10<>"Yes",Q10<>"ESD"),0,IF(S10="Cash capital",IF(T10<=15,IF(O10<>"",O10,MAX(0,N(H10)+N(K10))*IF(N10<>"",N10,M10)),0),IF(S10="Debt service",IF(T10>15,0,AK10*MAX(0,MIN(15-T10+1,U10))),IF(OR(S10="Annual O&M",S10="Maintenance-only"),IF(T10>15,0,IF(O10<>"",O10,MAX(0,N(H10)+N(K10))*IF(N10<>"",N10,M10))*MAX(0,15-T10+1)),0)))),0) -> 0 | AF10: =IFERROR(IF(OR(R10<>"Yes",Q10<>"ESD"),0,IF(S10="Cash capital",IF(T10<=20,IF(O10<>"",O10,MAX(0,N(I10)+N(K10))*IF(N10<>"",N10,M10)),0),IF(S10="Debt service",IF(T10>20,0,AL10*MAX(0,MIN(20-T10+1,U10))),IF(OR(S10="Annual O&M",S10="Maintenance-only"),IF(T10>20,0,IF(O10<>"",O10,MAX(0,N(I10)+N(K10))*IF(N10<>"",N10,M10))*MAX(0,20-T10+1)),0)))),0) -> 0 | AG10: =IFERROR(IF(OR(R10<>"Yes",Q10<>"ESD"),0,IF(S10="Cash capital",IF(T10<=30,IF(O10<>"",O10,MAX(0,N(J10)+N(K10))*IF(N10<>"",N10,M10)),0),IF(S10="Debt service",IF(T10>30,0,AM10*MAX(0,MIN(30-T10+1,U10))),IF(OR(S10="Annual O&M",S10="Maintenance-only"),IF(T10>30,0,IF(O10<>"",O10,MAX(0,N(J10)+N(K10))*IF(N10<>"",N10,M10))*MAX(0,30-T10+1)),0)))),0) -> 0 | AH10: Planning trigger only; topography and basin engineer review required. | Takeoff factor: 0.25 MGD; confidence Low; validate w/ Engineer/Public Works. | AI10: =IFERROR(IF(U10>0,IF(O10<>"",O10,MAX(0,N(F10)+N(K10))*IF(N10<>"",N10,M10))*IF(V10=0,1/U10,V10/(1-(1+V10)^(-U10))),0),0) -> 0 | AJ10: =IFERROR(IF(U10>0,IF(O10<>"",O10,MAX(0,N(G10)+N(K10))*IF(N10<>"",N10,M10))*IF(V10=0,1/U10,V10/(1-(1+V10)^(-U10))),0),0) -> 0 | AK10: =IFERROR(IF(U10>0,IF(O10<>"",O10,MAX(0,N(H10)+N(K10))*IF(N10<>"",N10,M10))*IF(V10=0,1/U10,V10/(1-(1+V10)^(-U10))),0),0) -> 0 | AL10: =IFERROR(IF(U10>0,IF(O10<>"",O10,MAX(0,N(I10)+N(K10))*IF(N10<>"",N10,M10))*IF(V10=0,1/U10,V10/(1-(1+V10)^(-U10))),0),0) -> 0 | AM10: =IFERROR(IF(U10>0,IF(O10<>"",O10,MAX(0,N(J10)+N(K10))*IF(N10<>"",N10,M10))*IF(V10=0,1/U10,V10/(1-(1+V10)^(-U10))),0),0) -> 0
A11: WWTP expansion capacity | B11: City | C11: sewer demand MGD | D11: MGD | E11: 250 gpd/LUE | F11: =(('03_Multi_Horizon_Results'!$B$22/'Advanced Inputs'!$D$50)*'12_Takeoff_Assumptions'!$B$14/1000000) -> 0.055 | G11: =(('03_Multi_Horizon_Results'!$C$22/'Advanced Inputs'!$D$50)*'12_Takeoff_Assumptions'!$B$14/1000000) -> 0.055 | H11: =(('03_Multi_Horizon_Results'!$D$22/'Advanced Inputs'!$D$50)*'12_Takeoff_Assumptions'!$B$14/1000000) -> 0.055 | I11: =(('03_Multi_Horizon_Results'!$E$22/'Advanced Inputs'!$D$50)*'12_Takeoff_Assumptions'!$B$14/1000000) -> 0.055 | J11: =(('03_Multi_Horizon_Results'!$F$22/'Advanced Inputs'!$D$50)*'12_Takeoff_Assumptions'!$B$14/1000000) -> 0.055 | L11: =MAX(0,N(G11)+N(K11)) -> 0.055 | M11: 6000000 | P11: =IFERROR(IF(O11<>"",O11,L11*IF(N11<>"",N11,M11)),0) -> 330000 | Q11: City | R11: Yes | S11: Debt service | T11: 1 | U11: 20 | V11: 0.045 | W11: =IFERROR(IF(AND(R11="Yes",S11="Debt service",U11>0),IF(V11=0,P11/U11,P11*V11/(1-(1+V11)^(-U11))),0),0) -> 25369.128 | X11: =IFERROR(IF(OR(R11<>"Yes",Q11<>"City"),0,IF(S11="Cash capital",IF(T11<=5,IF(O11<>"",O11,MAX(0,N(F11)+N(K11))*IF(N11<>"",N11,M11)),0),IF(S11="Debt service",IF(T11>5,0,AI11*MAX(0,MIN(5-T11+1,U11))),IF(OR(S11="Annual O&M",S11="Maintenance-only"),IF(T11>5,0,IF(O11<>"",O11,MAX(0,N(F11)+N(K11))*IF(N11<>"",N11,M11))*MAX(0,5-T11+1)),0)))),0) -> 126845.64 | Y11: =IFERROR(IF(OR(R11<>"Yes",Q11<>"City"),0,IF(S11="Cash capital",IF(T11<=10,IF(O11<>"",O11,MAX(0,N(G11)+N(K11))*IF(N11<>"",N11,M11)),0),IF(S11="Debt service",IF(T11>10,0,AJ11*MAX(0,MIN(10-T11+1,U11))),IF(OR(S11="Annual O&M",S11="Maintenance-only"),IF(T11>10,0,IF(O11<>"",O11,MAX(0,N(G11)+N(K11))*IF(N11<>"",N11,M11))*MAX(0,10-T11+1)),0)))),0) -> 253691.28 | Z11: =IFERROR(IF(OR(R11<>"Yes",Q11<>"City"),0,IF(S11="Cash capital",IF(T11<=15,IF(O11<>"",O11,MAX(0,N(H11)+N(K11))*IF(N11<>"",N11,M11)),0),IF(S11="Debt service",IF(T11>15,0,AK11*MAX(0,MIN(15-T11+1,U11))),IF(OR(S11="Annual O&M",S11="Maintenance-only"),IF(T11>15,0,IF(O11<>"",O11,MAX(0,N(H11)+N(K11))*IF(N11<>"",N11,M11))*MAX(0,15-T11+1)),0)))),0) -> 380536.91 | AA11: =IFERROR(IF(OR(R11<>"Yes",Q11<>"City"),0,IF(S11="Cash capital",IF(T11<=20,IF(O11<>"",O11,MAX(0,N(I11)+N(K11))*IF(N11<>"",N11,M11)),0),IF(S11="Debt service",IF(T11>20,0,AL11*MAX(0,MIN(20-T11+1,U11))),IF(OR(S11="Annual O&M",S11="Maintenance-only"),IF(T11>20,0,IF(O11<>"",O11,MAX(0,N(I11)+N(K11))*IF(N11<>"",N11,M11))*MAX(0,20-T11+1)),0)))),0) -> 507382.55 | AB11: =IFERROR(IF(OR(R11<>"Yes",Q11<>"City"),0,IF(S11="Cash capital",IF(T11<=30,IF(O11<>"",O11,MAX(0,N(J11)+N(K11))*IF(N11<>"",N11,M11)),0),IF(S11="Debt service",IF(T11>30,0,AM11*MAX(0,MIN(30-T11+1,U11))),IF(OR(S11="Annual O&M",S11="Maintenance-only"),IF(T11>30,0,IF(O11<>"",O11,MAX(0,N(J11)+N(K11))*IF(N11<>"",N11,M11))*MAX(0,30-T11+1)),0)))),0) -> 507382.55 | AC11: =IFERROR(IF(OR(R11<>"Yes",Q11<>"ESD"),0,IF(S11="Cash capital",IF(T11<=5,IF(O11<>"",O11,MAX(0,N(F11)+N(K11))*IF(N11<>"",N11,M11)),0),IF(S11="Debt service",IF(T11>5,0,AI11*MAX(0,MIN(5-T11+1,U11))),IF(OR(S11="Annual O&M",S11="Maintenance-only"),IF(T11>5,0,IF(O11<>"",O11,MAX(0,N(F11)+N(K11))*IF(N11<>"",N11,M11))*MAX(0,5-T11+1)),0)))),0) -> 0 | AD11: =IFERROR(IF(OR(R11<>"Yes",Q11<>"ESD"),0,IF(S11="Cash capital",IF(T11<=10,IF(O11<>"",O11,MAX(0,N(G11)+N(K11))*IF(N11<>"",N11,M11)),0),IF(S11="Debt service",IF(T11>10,0,AJ11*MAX(0,MIN(10-T11+1,U11))),IF(OR(S11="Annual O&M",S11="Maintenance-only"),IF(T11>10,0,IF(O11<>"",O11,MAX(0,N(G11)+N(K11))*IF(N11<>"",N11,M11))*MAX(0,10-T11+1)),0)))),0) -> 0 | AE11: =IFERROR(IF(OR(R11<>"Yes",Q11<>"ESD"),0,IF(S11="Cash capital",IF(T11<=15,IF(O11<>"",O11,MAX(0,N(H11)+N(K11))*IF(N11<>"",N11,M11)),0),IF(S11="Debt service",IF(T11>15,0,AK11*MAX(0,MIN(15-T11+1,U11))),IF(OR(S11="Annual O&M",S11="Maintenance-only"),IF(T11>15,0,IF(O11<>"",O11,MAX(0,N(H11)+N(K11))*IF(N11<>"",N11,M11))*MAX(0,15-T11+1)),0)))),0) -> 0 | AF11: =IFERROR(IF(OR(R11<>"Yes",Q11<>"ESD"),0,IF(S11="Cash capital",IF(T11<=20,IF(O11<>"",O11,MAX(0,N(I11)+N(K11))*IF(N11<>"",N11,M11)),0),IF(S11="Debt service",IF(T11>20,0,AL11*MAX(0,MIN(20-T11+1,U11))),IF(OR(S11="Annual O&M",S11="Maintenance-only"),IF(T11>20,0,IF(O11<>"",O11,MAX(0,N(I11)+N(K11))*IF(N11<>"",N11,M11))*MAX(0,20-T11+1)),0)))),0) -> 0 | AG11: =IFERROR(IF(OR(R11<>"Yes",Q11<>"ESD"),0,IF(S11="Cash capital",IF(T11<=30,IF(O11<>"",O11,MAX(0,N(J11)+N(K11))*IF(N11<>"",N11,M11)),0),IF(S11="Debt service",IF(T11>30,0,AM11*MAX(0,MIN(30-T11+1,U11))),IF(OR(S11="Annual O&M",S11="Maintenance-only"),IF(T11>30,0,IF(O11<>"",O11,MAX(0,N(J11)+N(K11))*IF(N11<>"",N11,M11))*MAX(0,30-T11+1)),0)))),0) -> 0 | AH11: Shows estimated sewer demand capacity exposure, not an engineering design directive. | Takeoff factor: 250 gpd per LUE; confidence Low; validate w/ Engineer/Public Works. | AI11: =IFERROR(IF(U11>0,IF(O11<>"",O11,MAX(0,N(F11)+N(K11))*IF(N11<>"",N11,M11))*IF(V11=0,1/U11,V11/(1-(1+V11)^(-U11))),0),0) -> 25369.128 | AJ11: =IFERROR(IF(U11>0,IF(O11<>"",O11,MAX(0,N(G11)+N(K11))*IF(N11<>"",N11,M11))*IF(V11=0,1/U11,V11/(1-(1+V11)^(-U11))),0),0) -> 25369.128 | AK11: =IFERROR(IF(U11>0,IF(O11<>"",O11,MAX(0,N(H11)+N(K11))*IF(N11<>"",N11,M11))*IF(V11=0,1/U11,V11/(1-(1+V11)^(-U11))),0),0) -> 25369.128 | AL11: =IFERROR(IF(U11>0,IF(O11<>"",O11,MAX(0,N(I11)+N(K11))*IF(N11<>"",N11,M11))*IF(V11=0,1/U11,V11/(1-(1+V11)^(-U11))),0),0) -> 25369.128 | AM11: =IFERROR(IF(U11>0,IF(O11<>"",O11,MAX(0,N(J11)+N(K11))*IF(N11<>"",N11,M11))*IF(V11=0,1/U11,V11/(1-(1+V11)^(-U11))),0),0) -> 25369.128
A12: Collector street | B12: City | C12: captured acres | D12: lane-miles | E12: 0.02 lane-mi/ac | F12: ='03_Multi_Horizon_Results'!$B$5*'12_Takeoff_Assumptions'!$B$7 -> 0.575 | G12: ='03_Multi_Horizon_Results'!$C$5*'12_Takeoff_Assumptions'!$B$7 -> 0.575 | H12: ='03_Multi_Horizon_Results'!$D$5*'12_Takeoff_Assumptions'!$B$7 -> 0.575 | I12: ='03_Multi_Horizon_Results'!$E$5*'12_Takeoff_Assumptions'!$B$7 -> 0.575 | J12: ='03_Multi_Horizon_Results'!$F$5*'12_Takeoff_Assumptions'!$B$7 -> 0.575 | L12: =MAX(0,N(G12)+N(K12)) -> 0.575 | M12: 750000 | P12: =IFERROR(IF(O12<>"",O12,L12*IF(N12<>"",N12,M12)),0) -> 431250 | Q12: City | R12: Yes | S12: Debt service | T12: 1 | U12: 20 | V12: 0.045 | W12: =IFERROR(IF(AND(R12="Yes",S12="Debt service",U12>0),IF(V12=0,P12/U12,P12*V12/(1-(1+V12)^(-U12))),0),0) -> 33152.837 | X12: =IFERROR(IF(OR(R12<>"Yes",Q12<>"City"),0,IF(S12="Cash capital",IF(T12<=5,IF(O12<>"",O12,MAX(0,N(F12)+N(K12))*IF(N12<>"",N12,M12)),0),IF(S12="Debt service",IF(T12>5,0,AI12*MAX(0,MIN(5-T12+1,U12))),IF(OR(S12="Annual O&M",S12="Maintenance-only"),IF(T12>5,0,IF(O12<>"",O12,MAX(0,N(F12)+N(K12))*IF(N12<>"",N12,M12))*MAX(0,5-T12+1)),0)))),0) -> 165764.19 | Y12: =IFERROR(IF(OR(R12<>"Yes",Q12<>"City"),0,IF(S12="Cash capital",IF(T12<=10,IF(O12<>"",O12,MAX(0,N(G12)+N(K12))*IF(N12<>"",N12,M12)),0),IF(S12="Debt service",IF(T12>10,0,AJ12*MAX(0,MIN(10-T12+1,U12))),IF(OR(S12="Annual O&M",S12="Maintenance-only"),IF(T12>10,0,IF(O12<>"",O12,MAX(0,N(G12)+N(K12))*IF(N12<>"",N12,M12))*MAX(0,10-T12+1)),0)))),0) -> 331528.37 | Z12: =IFERROR(IF(OR(R12<>"Yes",Q12<>"City"),0,IF(S12="Cash capital",IF(T12<=15,IF(O12<>"",O12,MAX(0,N(H12)+N(K12))*IF(N12<>"",N12,M12)),0),IF(S12="Debt service",IF(T12>15,0,AK12*MAX(0,MIN(15-T12+1,U12))),IF(OR(S12="Annual O&M",S12="Maintenance-only"),IF(T12>15,0,IF(O12<>"",O12,MAX(0,N(H12)+N(K12))*IF(N12<>"",N12,M12))*MAX(0,15-T12+1)),0)))),0) -> 497292.56 | AA12: =IFERROR(IF(OR(R12<>"Yes",Q12<>"City"),0,IF(S12="Cash capital",IF(T12<=20,IF(O12<>"",O12,MAX(0,N(I12)+N(K12))*IF(N12<>"",N12,M12)),0),IF(S12="Debt service",IF(T12>20,0,AL12*MAX(0,MIN(20-T12+1,U12))),IF(OR(S12="Annual O&M",S12="Maintenance-only"),IF(T12>20,0,IF(O12<>"",O12,MAX(0,N(I12)+N(K12))*IF(N12<>"",N12,M12))*MAX(0,20-T12+1)),0)))),0) -> 663056.74 | AB12: =IFERROR(IF(OR(R12<>"Yes",Q12<>"City"),0,IF(S12="Cash capital",IF(T12<=30,IF(O12<>"",O12,MAX(0,N(J12)+N(K12))*IF(N12<>"",N12,M12)),0),IF(S12="Debt service",IF(T12>30,0,AM12*MAX(0,MIN(30-T12+1,U12))),IF(OR(S12="Annual O&M",S12="Maintenance-only"),IF(T12>30,0,IF(O12<>"",O12,MAX(0,N(J12)+N(K12))*IF(N12<>"",N12,M12))*MAX(0,30-T12+1)),0)))),0) -> 663056.74 | AC12: =IFERROR(IF(OR(R12<>"Yes",Q12<>"ESD"),0,IF(S12="Cash capital",IF(T12<=5,IF(O12<>"",O12,MAX(0,N(F12)+N(K12))*IF(N12<>"",N12,M12)),0),IF(S12="Debt service",IF(T12>5,0,AI12*MAX(0,MIN(5-T12+1,U12))),IF(OR(S12="Annual O&M",S12="Maintenance-only"),IF(T12>5,0,IF(O12<>"",O12,MAX(0,N(F12)+N(K12))*IF(N12<>"",N12,M12))*MAX(0,5-T12+1)),0)))),0) -> 0 | AD12: =IFERROR(IF(OR(R12<>"Yes",Q12<>"ESD"),0,IF(S12="Cash capital",IF(T12<=10,IF(O12<>"",O12,MAX(0,N(G12)+N(K12))*IF(N12<>"",N12,M12)),0),IF(S12="Debt service",IF(T12>10,0,AJ12*MAX(0,MIN(10-T12+1,U12))),IF(OR(S12="Annual O&M",S12="Maintenance-only"),IF(T12>10,0,IF(O12<>"",O12,MAX(0,N(G12)+N(K12))*IF(N12<>"",N12,M12))*MAX(0,10-T12+1)),0)))),0) -> 0 | AE12: =IFERROR(IF(OR(R12<>"Yes",Q12<>"ESD"),0,IF(S12="Cash capital",IF(T12<=15,IF(O12<>"",O12,MAX(0,N(H12)+N(K12))*IF(N12<>"",N12,M12)),0),IF(S12="Debt service",IF(T12>15,0,AK12*MAX(0,MIN(15-T12+1,U12))),IF(OR(S12="Annual O&M",S12="Maintenance-only"),IF(T12>15,0,IF(O12<>"",O12,MAX(0,N(H12)+N(K12))*IF(N12<>"",N12,M12))*MAX(0,15-T12+1)),0)))),0) -> 0 | AF12: =IFERROR(IF(OR(R12<>"Yes",Q12<>"ESD"),0,IF(S12="Cash capital",IF(T12<=20,IF(O12<>"",O12,MAX(0,N(I12)+N(K12))*IF(N12<>"",N12,M12)),0),IF(S12="Debt service",IF(T12>20,0,AL12*MAX(0,MIN(20-T12+1,U12))),IF(OR(S12="Annual O&M",S12="Maintenance-only"),IF(T12>20,0,IF(O12<>"",O12,MAX(0,N(I12)+N(K12))*IF(N12<>"",N12,M12))*MAX(0,20-T12+1)),0)))),0) -> 0 | AG12: =IFERROR(IF(OR(R12<>"Yes",Q12<>"ESD"),0,IF(S12="Cash capital",IF(T12<=30,IF(O12<>"",O12,MAX(0,N(J12)+N(K12))*IF(N12<>"",N12,M12)),0),IF(S12="Debt service",IF(T12>30,0,AM12*MAX(0,MIN(30-T12+1,U12))),IF(OR(S12="Annual O&M",S12="Maintenance-only"),IF(T12>30,0,IF(O12<>"",O12,MAX(0,N(J12)+N(K12))*IF(N12<>"",N12,M12))*MAX(0,30-T12+1)),0)))),0) -> 0 | AH12: Thoroughfare planning allowance; actual route/section should override. | Takeoff factor: 0.02 lane-mile per developed acre; confidence Low; validate w/ Public Works/Engineer. | AI12: =IFERROR(IF(U12>0,IF(O12<>"",O12,MAX(0,N(F12)+N(K12))*IF(N12<>"",N12,M12))*IF(V12=0,1/U12,V12/(1-(1+V12)^(-U12))),0),0) -> 33152.837 | AJ12: =IFERROR(IF(U12>0,IF(O12<>"",O12,MAX(0,N(G12)+N(K12))*IF(N12<>"",N12,M12))*IF(V12=0,1/U12,V12/(1-(1+V12)^(-U12))),0),0) -> 33152.837 | AK12: =IFERROR(IF(U12>0,IF(O12<>"",O12,MAX(0,N(H12)+N(K12))*IF(N12<>"",N12,M12))*IF(V12=0,1/U12,V12/(1-(1+V12)^(-U12))),0),0) -> 33152.837 | AL12: =IFERROR(IF(U12>0,IF(O12<>"",O12,MAX(0,N(I12)+N(K12))*IF(N12<>"",N12,M12))*IF(V12=0,1/U12,V12/(1-(1+V12)^(-U12))),0),0) -> 33152.837 | AM12: =IFERROR(IF(U12>0,IF(O12<>"",O12,MAX(0,N(J12)+N(K12))*IF(N12<>"",N12,M12))*IF(V12=0,1/U12,V12/(1-(1+V12)^(-U12))),0),0) -> 33152.837
