Workbook

Sheet INPUTS
A1: INPUTS — all user-editable assumptions (edit the yellow 'Your input' column)
A2: Recommended values + their basis are shown for reference. Scenario projects are on the 'Scenarios' tab; large capital items on 'Capital_Items'. Results on 'RESULTS'.
A4: Assumption | B4: Recommended | C4: Basis / source | D4: Your input
A5: A. ALLOCATION & TAX RATES
A6: City General Fund share of sales-tax pool | B6: 50% | C6: User input; no preferred split implied | D6: 0.5
A7: EDC retention (% of City share) | B7: 0% | C7: MODELING ASSUMPTION — subject to City Attorney (Tex LGC Ch.505) | D7: 0
A8: ESD #2 share of sales-tax pool | B8: 50% | C8: User input; City + ESD must = 100% | D8: 0.5
A9: Sales-tax pool rate | B9: 1.5% | C9: Combined-area code 6008609; 2.0% local cap (Tex Tax Ch.321) | D9: 0.015
A10: City property tax rate (per $1 AV) | B10: 0.0037731 | C10: Sealy FY26 Ord. 2025-24 ($0.37731/$100) | D10: 0.0037731
A11: ESD #2 property tax rate (per $1 AV) | B11: 0.000931 | C11: ESD #2 2026 ($0.09310/$100); FY25 ACFR confirms | D11: 0.000931
A12: B. GROWTH & FINANCIAL
A13: Sealy current population | B13: 7,553 | C13: HB1378 §140.008 FY25; FY25 ACFR cross-val | D13: 7553
A14: Population CAGR | B14: 3.2% | C14: HB1378 5-yr actual 6,450→7,553 | D14: 0.032
A15: Current annual sales-tax pool ($) | B15: 3,700,000 | C15: FY26 Adopted Budget (conservative floor) | D15: 3700000
A16: Sales-tax pool CAGR | B16: 6.5% | C16: Sealy 12-yr Comptroller; 9% high-case sensitivity | D16: 0.065
A17: Property AV growth CAGR | B17: 6.0% | C17: HB1378-derived; 5-yr was 7.3% (conservative) | D17: 0.06
A18: Annexation capture rate | B18: 80% | C18: Planning benchmark; per-project adjustable | D18: 0.8
A19: General opex inflation CAGR | B19: 2.5% | C19: TML benchmark | D19: 0.025
A20: Capital construction inflation CAGR | B20: 4.5% | C20: Maxxbuilders TX 2024-2026 (3-6%) | D20: 0.045
A21: City reserve % (opex+capital basis) | B21: 2.5% | C21: Planning benchmark | D21: 0.025
A22: ESD reserve % (opex+capital basis) | B22: 2.5% | C22: Planning benchmark | D22: 0.025
A23: Reserve basis includes capital? (1=Yes,0=No) | B23: 1 | C23: Spec #13 Option B | D23: 1
A24: Property tax collection rate | B24: 100% | C24: FY25 ACFR collected ~104.6%; default 100% | D24: 1
A25: C. RESIDENT ONLINE / DELIVERY USE-TAX
A26: SFR occupancy rate | B26: 95% | C26: Planning benchmark | D26: 0.95
A27: MFR occupancy rate | B27: 92% | C27: Retreat at Sealy lease-up | D27: 0.92
A28: SFR household size | B28: 2.7 | C28: Census-derived | D28: 2.7
A29: MFR household size | B29: 2.1 | C29: Retreat at Sealy | D29: 2.1
A30: Online spend per occupied household ($) | B30: 6,000 | C30: Base case; $4K cons / $8K high | D30: 6000
A31: Taxable share of online spending | B31: 70% | C31: Marketplace + remote-seller scope | D31: 0.7
A32: Local address capture factor | B32: 75% | C32: Destination ship-to to Sealy/ESD combined area | D32: 0.75
A33: Online spend growth (CAGR) | B33: 4% | C33: Real growth/HH | D33: 0.04
A34: Include online use-tax? (1=Yes,0=No) | B34: 1 | C34: Toggle (Test 11/12) | D34: 1
A36: D. EXEMPTION ADJUSTMENT — effective taxable-value factor (edit % cells; factor = 1 − sum)
A37: Category | B37: Homestead% | C37: Over65% | D37: DisVet% | E37: Freeport% | F37: Pollution% | G37: Other% | H37: Haircut | I37: Factor | J37: ESD Hmstd% | K37: ESD Ov65% | L37: ESD DVet% | M37: ESD Free% | N37: ESD Poll% | O37: ESD Other% | P37: ESD Haircut | Q37: ESD Factor
A38: Residential | B38: 0 | C38: 0.005 | D38: 0.015 | E38: 0 | F38: 0 | G38: 0 | H38: =SUM(B38:G38) | I38: =MAX(0,1-H38) | J38: 0.015 | K38: 0.005 | L38: 0.015 | M38: 0 | N38: 0 | O38: 0 | P38: =SUM(J38:O38) | Q38: =MAX(0,1-P38)
A39: Commercial | B39: 0 | C39: 0 | D39: 0 | E39: 0 | F39: 0 | G39: 0.01 | H39: =SUM(B39:G39) | I39: =MAX(0,1-H39) | J39: 0 | K39: 0 | L39: 0 | M39: 0 | N39: 0 | O39: 0.01 | P39: =SUM(J39:O39) | Q39: =MAX(0,1-P39)
A40: Industrial | B40: 0 | C40: 0 | D40: 0 | E40: 0.05 | F40: 0.02 | G40: 0.01 | H40: =SUM(B40:G40) | I40: =MAX(0,1-H40) | J40: 0 | K40: 0 | L40: 0 | M40: 0.05 | N40: 0.02 | O40: 0.01 | P40: =SUM(J40:O40) | Q40: =MAX(0,1-P40)
A41: Civic | B41: 0 | C41: 0 | D41: 0 | E41: 0 | F41: 0 | G41: 1 | H41: =SUM(B41:G41) | I41: =MAX(0,1-H41) | J41: 0 | K41: 0 | L41: 0 | M41: 0 | N41: 0 | O41: 1 | P41: =SUM(J41:O41) | Q41: =MAX(0,1-P41)
A42: Vacant | B42: 0 | C42: 0 | D42: 0 | E42: 0 | F42: 0 | G42: 0 | H42: =SUM(B42:G42) | I42: =MAX(0,1-H42) | J42: 0 | K42: 0 | L42: 0 | M42: 0 | N42: 0 | O42: 0 | P42: =SUM(J42:O42) | Q42: =MAX(0,1-P42)
...

Sheet Capital_Items
A1: Capital Items — large infrastructure & equipment (set the white cells; results flow to RESULTS)
A2: HOW TO READ: Quantities are CUMULATIVE totals at buildout, NOT per-year — a value that's the same across years just means that item is fully built and not still growing. A cost affects City/ESD NET only when 'Include in net?' = Yes AND 'Who pays' = City or ESD (choosing Developer or another payer removes it from the fiscal net). 'How it's paid' = Cash capital (one-time) or Debt service (financed over the term).
A3: Item | B3: Entity | C3: Driver (what triggers qty) | D3: Unit | E3: Typical factor | F3: 5-year auto qty | G3: 10-year auto qty | H3: 15-year auto qty | I3: 20-year auto qty | J3: 30-year auto qty | K3: Manual qty +/- | L3: Cumulative quantity (at buildout) | M3: Unit cost ($) | N3: Unit cost override | O3: Manual Total Cost Override | P3: Total cost (today's $) | Q3: Who pays | R3: Include in net? | S3: How it's paid | T3: Start year | U3: Debt term (yrs) | V3: Debt rate | W3: Annual Debt Service | X3: City 5-year impact | Y3: City 10-year impact | Z3: City 15-year impact | AA3: City 20-year impact | AB3: City 30-year impact | AC3: ESD 5-year impact | AD3: ESD 10-year impact | AE3: ESD 15-year impact | AF3: ESD 20-year impact | AG3: ESD 30-year impact | AH3: Source / Note
A4: 12-inch water main, transmission | B4: City | C4: captured acres | D4: linear ft | E4: 60 LF/ac | F4: ='03_Multi_Horizon_Results'!$B$5*'12_Takeoff_Assumptions'!$B$3 | G4: ='03_Multi_Horizon_Results'!$C$5*'12_Takeoff_Assumptions'!$B$3 | H4: ='03_Multi_Horizon_Results'!$D$5*'12_Takeoff_Assumptions'!$B$3 | I4: ='03_Multi_Horizon_Results'!$E$5*'12_Takeoff_Assumptions'!$B$3 | J4: ='03_Multi_Horizon_Results'!$F$5*'12_Takeoff_Assumptions'!$B$3 | L4: =MAX(0,N(G4)+N(K4)) | M4: 600 | P4: =IFERROR(IF(O4<>"",O4,L4*IF(N4<>"",N4,M4)),0) | Q4: City | R4: No | S4: Debt service | T4: 1 | U4: 20 | V4: 0.045 | W4: =IFERROR(IF(AND(R4="Yes",S4="Debt service",U4>0),IF(V4=0,P4/U4,P4*V4/(1-(1+V4)^(-U4))),0),0) | X4: =IFERROR(IF(OR(R4<>"Yes",Q4<>"City"),0,IF(S4="Cash capital",IF(T4<=5,IF(O4<>"",O4,MAX(0,N(F4)+N(K4))*IF(N4<>"",N4,M4)),0),IF(S4="Debt service",IF(T4>5,0,W4*MAX(0,MIN(5-T4+1,U4))),IF(OR(S4="Annual O&M",S4="Maintenance-only"),IF(T4>5,0,IF(O4<>"",O4,MAX(0,N(F4)+N(K4))*IF(N4<>"",N4,M4))*MAX(0,5-T4+1)),0)))),0) | Y4: =IFERROR(IF(OR(R4<>"Yes",Q4<>"City"),0,IF(S4="Cash capital",IF(T4<=10,IF(O4<>"",O4,MAX(0,N(G4)+N(K4))*IF(N4<>"",N4,M4)),0),IF(S4="Debt service",IF(T4>10,0,W4*MAX(0,MIN(10-T4+1,U4))),IF(OR(S4="Annual O&M",S4="Maintenance-only"),IF(T4>10,0,IF(O4<>"",O4,MAX(0,N(G4)+N(K4))*IF(N4<>"",N4,M4))*MAX(0,10-T4+1)),0)))),0) | Z4: =IFERROR(IF(OR(R4<>"Yes",Q4<>"City"),0,IF(S4="Cash capital",IF(T4<=15,IF(O4<>"",O4,MAX(0,N(H4)+N(K4))*IF(N4<>"",N4,M4)),0),IF(S4="Debt service",IF(T4>15,0,W4*MAX(0,MIN(15-T4+1,U4))),IF(OR(S4="Annual O&M",S4="Maintenance-only"),IF(T4>15,0,IF(O4<>"",O4,MAX(0,N(H4)+N(K4))*IF(N4<>"",N4,M4))*MAX(0,15-T4+1)),0)))),0) | AA4: =IFERROR(IF(OR(R4<>"Yes",Q4<>"City"),0,IF(S4="Cash capital",IF(T4<=20,IF(O4<>"",O4,MAX(0,N(I4)+N(K4))*IF(N4<>"",N4,M4)),0),IF(S4="Debt service",IF(T4>20,0,W4*MAX(0,MIN(20-T4+1,U4))),IF(OR(S4="Annual O&M",S4="Maintenance-only"),IF(T4>20,0,IF(O4<>"",O4,MAX(0,N(I4)+N(K4))*IF(N4<>"",N4,M4))*MAX(0,20-T4+1)),0)))),0) | AB4: =IFERROR(IF(OR(R4<>"Yes",Q4<>"City"),0,IF(S4="Cash capital",IF(T4<=30,IF(O4<>"",O4,MAX(0,N(J4)+N(K4))*IF(N4<>"",N4,M4)),0),IF(S4="Debt service",IF(T4>30,0,W4*MAX(0,MIN(30-T4+1,U4))),IF(OR(S4="Annual O&M",S4="Maintenance-only"),IF(T4>30,0,IF(O4<>"",O4,MAX(0,N(J4)+N(K4))*IF(N4<>"",N4,M4))*MAX(0,30-T4+1)),0)))),0) | AC4: =IFERROR(IF(OR(R4<>"Yes",Q4<>"ESD"),0,IF(S4="Cash capital",IF(T4<=5,IF(O4<>"",O4,MAX(0,N(F4)+N(K4))*IF(N4<>"",N4,M4)),0),IF(S4="Debt service",IF(T4>5,0,W4*MAX(0,MIN(5-T4+1,U4))),IF(OR(S4="Annual O&M",S4="Maintenance-only"),IF(T4>5,0,IF(O4<>"",O4,MAX(0,N(F4)+N(K4))*IF(N4<>"",N4,M4))*MAX(0,5-T4+1)),0)))),0) | AD4: =IFERROR(IF(OR(R4<>"Yes",Q4<>"ESD"),0,IF(S4="Cash capital",IF(T4<=10,IF(O4<>"",O4,MAX(0,N(G4)+N(K4))*IF(N4<>"",N4,M4)),0),IF(S4="Debt service",IF(T4>10,0,W4*MAX(0,MIN(10-T4+1,U4))),IF(OR(S4="Annual O&M",S4="Maintenance-only"),IF(T4>10,0,IF(O4<>"",O4,MAX(0,N(G4)+N(K4))*IF(N4<>"",N4,M4))*MAX(0,10-T4+1)),0)))),0) | AE4: =IFERROR(IF(OR(R4<>"Yes",Q4<>"ESD"),0,IF(S4="Cash capital",IF(T4<=15,IF(O4<>"",O4,MAX(0,N(H4)+N(K4))*IF(N4<>"",N4,M4)),0),IF(S4="Debt service",IF(T4>15,0,W4*MAX(0,MIN(15-T4+1,U4))),IF(OR(S4="Annual O&M",S4="Maintenance-only"),IF(T4>15,0,IF(O4<>"",O4,MAX(0,N(H4)+N(K4))*IF(N4<>"",N4,M4))*MAX(0,15-T4+1)),0)))),0) | AF4: =IFERROR(IF(OR(R4<>"Yes",Q4<>"ESD"),0,IF(S4="Cash capital",IF(T4<=20,IF(O4<>"",O4,MAX(0,N(I4)+N(K4))*IF(N4<>"",N4,M4)),0),IF(S4="Debt service",IF(T4>20,0,W4*MAX(0,MIN(20-T4+1,U4))),IF(OR(S4="Annual O&M",S4="Maintenance-only"),IF(T4>20,0,IF(O4<>"",O4,MAX(0,N(I4)+N(K4))*IF(N4<>"",N4,M4))*MAX(0,20-T4+1)),0)))),0) | AG4: =IFERROR(IF(OR(R4<>"Yes",Q4<>"ESD"),0,IF(S4="Cash capital",IF(T4<=30,IF(O4<>"",O4,MAX(0,N(J4)+N(K4))*IF(N4<>"",N4,M4)),0),IF(S4="Debt service",IF(T4>30,0,W4*MAX(0,MIN(30-T4+1,U4))),IF(OR(S4="Annual O&M",S4="Maintenance-only"),IF(T4>30,0,IF(O4<>"",O4,MAX(0,N(J4)+N(K4))*IF(N4<>"",N4,M4))*MAX(0,30-T4+1)),0)))),0) | AH4: Planning allowance for trunk/looping needs; engineer/Public Works validation required.
A5: 8-inch water main, distribution | B5: City | C5: captured acres | D5: linear ft | E5: 400 LF/ac | F5: ='03_Multi_Horizon_Results'!$B$5*'12_Takeoff_Assumptions'!$B$2 | G5: ='03_Multi_Horizon_Results'!$C$5*'12_Takeoff_Assumptions'!$B$2 | H5: ='03_Multi_Horizon_Results'!$D$5*'12_Takeoff_Assumptions'!$B$2 | I5: ='03_Multi_Horizon_Results'!$E$5*'12_Takeoff_Assumptions'!$B$2 | J5: ='03_Multi_Horizon_Results'!$F$5*'12_Takeoff_Assumptions'!$B$2 | L5: =MAX(0,N(G5)+N(K5)) | M5: 250 | P5: =IFERROR(IF(O5<>"",O5,L5*IF(N5<>"",N5,M5)),0) | Q5: City | R5: No | S5: Debt service | T5: 1 | U5: 20 | V5: 0.045 | W5: =IFERROR(IF(AND(R5="Yes",S5="Debt service",U5>0),IF(V5=0,P5/U5,P5*V5/(1-(1+V5)^(-U5))),0),0) | X5: =IFERROR(IF(OR(R5<>"Yes",Q5<>"City"),0,IF(S5="Cash capital",IF(T5<=5,IF(O5<>"",O5,MAX(0,N(F5)+N(K5))*IF(N5<>"",N5,M5)),0),IF(S5="Debt service",IF(T5>5,0,W5*MAX(0,MIN(5-T5+1,U5))),IF(OR(S5="Annual O&M",S5="Maintenance-only"),IF(T5>5,0,IF(O5<>"",O5,MAX(0,N(F5)+N(K5))*IF(N5<>"",N5,M5))*MAX(0,5-T5+1)),0)))),0) | Y5: =IFERROR(IF(OR(R5<>"Yes",Q5<>"City"),0,IF(S5="Cash capital",IF(T5<=10,IF(O5<>"",O5,MAX(0,N(G5)+N(K5))*IF(N5<>"",N5,M5)),0),IF(S5="Debt service",IF(T5>10,0,W5*MAX(0,MIN(10-T5+1,U5))),IF(OR(S5="Annual O&M",S5="Maintenance-only"),IF(T5>10,0,IF(O5<>"",O5,MAX(0,N(G5)+N(K5))*IF(N5<>"",N5,M5))*MAX(0,10-T5+1)),0)))),0) | Z5: =IFERROR(IF(OR(R5<>"Yes",Q5<>"City"),0,IF(S5="Cash capital",IF(T5<=15,IF(O5<>"",O5,MAX(0,N(H5)+N(K5))*IF(N5<>"",N5,M5)),0),IF(S5="Debt service",IF(T5>15,0,W5*MAX(0,MIN(15-T5+1,U5))),IF(OR(S5="Annual O&M",S5="Maintenance-only"),IF(T5>15,0,IF(O5<>"",O5,MAX(0,N(H5)+N(K5))*IF(N5<>"",N5,M5))*MAX(0,15-T5+1)),0)))),0) | AA5: =IFERROR(IF(OR(R5<>"Yes",Q5<>"City"),0,IF(S5="Cash capital",IF(T5<=20,IF(O5<>"",O5,MAX(0,N(I5)+N(K5))*IF(N5<>"",N5,M5)),0),IF(S5="Debt service",IF(T5>20,0,W5*MAX(0,MIN(20-T5+1,U5))),IF(OR(S5="Annual O&M",S5="Maintenance-only"),IF(T5>20,0,IF(O5<>"",O5,MAX(0,N(I5)+N(K5))*IF(N5<>"",N5,M5))*MAX(0,20-T5+1)),0)))),0) | AB5: =IFERROR(IF(OR(R5<>"Yes",Q5<>"City"),0,IF(S5="Cash capital",IF(T5<=30,IF(O5<>"",O5,MAX(0,N(J5)+N(K5))*IF(N5<>"",N5,M5)),0),IF(S5="Debt service",IF(T5>30,0,W5*MAX(0,MIN(30-T5+1,U5))),IF(OR(S5="Annual O&M",S5="Maintenance-only"),IF(T5>30,0,IF(O5<>"",O5,MAX(0,N(J5)+N(K5))*IF(N5<>"",N5,M5))*MAX(0,30-T5+1)),0)))),0) | AC5: =IFERROR(IF(OR(R5<>"Yes",Q5<>"ESD"),0,IF(S5="Cash capital",IF(T5<=5,IF(O5<>"",O5,MAX(0,N(F5)+N(K5))*IF(N5<>"",N5,M5)),0),IF(S5="Debt service",IF(T5>5,0,W5*MAX(0,MIN(5-T5+1,U5))),IF(OR(S5="Annual O&M",S5="Maintenance-only"),IF(T5>5,0,IF(O5<>"",O5,MAX(0,N(F5)+N(K5))*IF(N5<>"",N5,M5))*MAX(0,5-T5+1)),0)))),0) | AD5: =IFERROR(IF(OR(R5<>"Yes",Q5<>"ESD"),0,IF(S5="Cash capital",IF(T5<=10,IF(O5<>"",O5,MAX(0,N(G5)+N(K5))*IF(N5<>"",N5,M5)),0),IF(S5="Debt service",IF(T5>10,0,W5*MAX(0,MIN(10-T5+1,U5))),IF(OR(S5="Annual O&M",S5="Maintenance-only"),IF(T5>10,0,IF(O5<>"",O5,MAX(0,N(G5)+N(K5))*IF(N5<>"",N5,M5))*MAX(0,10-T5+1)),0)))),0) | AE5: =IFERROR(IF(OR(R5<>"Yes",Q5<>"ESD"),0,IF(S5="Cash capital",IF(T5<=15,IF(O5<>"",O5,MAX(0,N(H5)+N(K5))*IF(N5<>"",N5,M5)),0),IF(S5="Debt service",IF(T5>15,0,W5*MAX(0,MIN(15-T5+1,U5))),IF(OR(S5="Annual O&M",S5="Maintenance-only"),IF(T5>15,0,IF(O5<>"",O5,MAX(0,N(H5)+N(K5))*IF(N5<>"",N5,M5))*MAX(0,15-T5+1)),0)))),0) | AF5: =IFERROR(IF(OR(R5<>"Yes",Q5<>"ESD"),0,IF(S5="Cash capital",IF(T5<=20,IF(O5<>"",O5,MAX(0,N(I5)+N(K5))*IF(N5<>"",N5,M5)),0),IF(S5="Debt service",IF(T5>20,0,W5*MAX(0,MIN(20-T5+1,U5))),IF(OR(S5="Annual O&M",S5="Maintenance-only"),IF(T5>20,0,IF(O5<>"",O5,MAX(0,N(I5)+N(K5))*IF(N5<>"",N5,M5))*MAX(0,20-T5+1)),0)))),0) | AG5: =IFERROR(IF(OR(R5<>"Yes",Q5<>"ESD"),0,IF(S5="Cash capital",IF(T5<=30,IF(O5<>"",O5,MAX(0,N(J5)+N(K5))*IF(N5<>"",N5,M5)),0),IF(S5="Debt service",IF(T5>30,0,W5*MAX(0,MIN(30-T5+1,U5))),IF(OR(S5="Annual O&M",S5="Maintenance-only"),IF(T5>30,0,IF(O5<>"",O5,MAX(0,N(J5)+N(K5))*IF(N5<>"",N5,M5))*MAX(0,30-T5+1)),0)))),0) | AH5: Subdivision/internal water distribution planning allowance; actual plat should override.
A6: Fire hydrants | B6: City | C6: water distribution LF | D6: each | E6: hydrant spacing 500 LF | F6: =IFERROR(ROUNDUP(('03_Multi_Horizon_Results'!$B$5*'12_Takeoff_Assumptions'!$B$2)/'12_Takeoff_Assumptions'!$B$9,0),0) | G6: =IFERROR(ROUNDUP(('03_Multi_Horizon_Results'!$C$5*'12_Takeoff_Assumptions'!$B$2)/'12_Takeoff_Assumptions'!$B$9,0),0) | H6: =IFERROR(ROUNDUP(('03_Multi_Horizon_Results'!$D$5*'12_Takeoff_Assumptions'!$B$2)/'12_Takeoff_Assumptions'!$B$9,0),0) | I6: =IFERROR(ROUNDUP(('03_Multi_Horizon_Results'!$E$5*'12_Takeoff_Assumptions'!$B$2)/'12_Takeoff_Assumptions'!$B$9,0),0) | J6: =IFERROR(ROUNDUP(('03_Multi_Horizon_Results'!$F$5*'12_Takeoff_Assumptions'!$B$2)/'12_Takeoff_Assumptions'!$B$9,0),0) | L6: =MAX(0,N(G6)+N(K6)) | M6: 7500 | P6: =IFERROR(IF(O6<>"",O6,L6*IF(N6<>"",N6,M6)),0) | Q6: City | R6: No | S6: Debt service | T6: 1 | U6: 20 | V6: 0.045 | W6: =IFERROR(IF(AND(R6="Yes",S6="Debt service",U6>0),IF(V6=0,P6/U6,P6*V6/(1-(1+V6)^(-U6))),0),0) | X6: =IFERROR(IF(OR(R6<>"Yes",Q6<>"City"),0,IF(S6="Cash capital",IF(T6<=5,IF(O6<>"",O6,MAX(0,N(F6)+N(K6))*IF(N6<>"",N6,M6)),0),IF(S6="Debt service",IF(T6>5,0,W6*MAX(0,MIN(5-T6+1,U6))),IF(OR(S6="Annual O&M",S6="Maintenance-only"),IF(T6>5,0,IF(O6<>"",O6,MAX(0,N(F6)+N(K6))*IF(N6<>"",N6,M6))*MAX(0,5-T6+1)),0)))),0) | Y6: =IFERROR(IF(OR(R6<>"Yes",Q6<>"City"),0,IF(S6="Cash capital",IF(T6<=10,IF(O6<>"",O6,MAX(0,N(G6)+N(K6))*IF(N6<>"",N6,M6)),0),IF(S6="Debt service",IF(T6>10,0,W6*MAX(0,MIN(10-T6+1,U6))),IF(OR(S6="Annual O&M",S6="Maintenance-only"),IF(T6>10,0,IF(O6<>"",O6,MAX(0,N(G6)+N(K6))*IF(N6<>"",N6,M6))*MAX(0,10-T6+1)),0)))),0) | Z6: =IFERROR(IF(OR(R6<>"Yes",Q6<>"City"),0,IF(S6="Cash capital",IF(T6<=15,IF(O6<>"",O6,MAX(0,N(H6)+N(K6))*IF(N6<>"",N6,M6)),0),IF(S6="Debt service",IF(T6>15,0,W6*MAX(0,MIN(15-T6+1,U6))),IF(OR(S6="Annual O&M",S6="Maintenance-only"),IF(T6>15,0,IF(O6<>"",O6,MAX(0,N(H6)+N(K6))*IF(N6<>"",N6,M6))*MAX(0,15-T6+1)),0)))),0) | AA6: =IFERROR(IF(OR(R6<>"Yes",Q6<>"City"),0,IF(S6="Cash capital",IF(T6<=20,IF(O6<>"",O6,MAX(0,N(I6)+N(K6))*IF(N6<>"",N6,M6)),0),IF(S6="Debt service",IF(T6>20,0,W6*MAX(0,MIN(20-T6+1,U6))),IF(OR(S6="Annual O&M",S6="Maintenance-only"),IF(T6>20,0,IF(O6<>"",O6,MAX(0,N(I6)+N(K6))*IF(N6<>"",N6,M6))*MAX(0,20-T6+1)),0)))),0) | AB6: =IFERROR(IF(OR(R6<>"Yes",Q6<>"City"),0,IF(S6="Cash capital",IF(T6<=30,IF(O6<>"",O6,MAX(0,N(J6)+N(K6))*IF(N6<>"",N6,M6)),0),IF(S6="Debt service",IF(T6>30,0,W6*MAX(0,MIN(30-T6+1,U6))),IF(OR(S6="Annual O&M",S6="Maintenance-only"),IF(T6>30,0,IF(O6<>"",O6,MAX(0,N(J6)+N(K6))*IF(N6<>"",N6,M6))*MAX(0,30-T6+1)),0)))),0) | AC6: =IFERROR(IF(OR(R6<>"Yes",Q6<>"ESD"),0,IF(S6="Cash capital",IF(T6<=5,IF(O6<>"",O6,MAX(0,N(F6)+N(K6))*IF(N6<>"",N6,M6)),0),IF(S6="Debt service",IF(T6>5,0,W6*MAX(0,MIN(5-T6+1,U6))),IF(OR(S6="Annual O&M",S6="Maintenance-only"),IF(T6>5,0,IF(O6<>"",O6,MAX(0,N(F6)+N(K6))*IF(N6<>"",N6,M6))*MAX(0,5-T6+1)),0)))),0) | AD6: =IFERROR(IF(OR(R6<>"Yes",Q6<>"ESD"),0,IF(S6="Cash capital",IF(T6<=10,IF(O6<>"",O6,MAX(0,N(G6)+N(K6))*IF(N6<>"",N6,M6)),0),IF(S6="Debt service",IF(T6>10,0,W6*MAX(0,MIN(10-T6+1,U6))),IF(OR(S6="Annual O&M",S6="Maintenance-only"),IF(T6>10,0,IF(O6<>"",O6,MAX(0,N(G6)+N(K6))*IF(N6<>"",N6,M6))*MAX(0,10-T6+1)),0)))),0) | AE6: =IFERROR(IF(OR(R6<>"Yes",Q6<>"ESD"),0,IF(S6="Cash capital",IF(T6<=15,IF(O6<>"",O6,MAX(0,N(H6)+N(K6))*IF(N6<>"",N6,M6)),0),IF(S6="Debt service",IF(T6>15,0,W6*MAX(0,MIN(15-T6+1,U6))),IF(OR(S6="Annual O&M",S6="Maintenance-only"),IF(T6>15,0,IF(O6<>"",O6,MAX(0,N(H6)+N(K6))*IF(N6<>"",N6,M6))*MAX(0,15-T6+1)),0)))),0) | AF6: =IFERROR(IF(OR(R6<>"Yes",Q6<>"ESD"),0,IF(S6="Cash capital",IF(T6<=20,IF(O6<>"",O6,MAX(0,N(I6)+N(K6))*IF(N6<>"",N6,M6)),0),IF(S6="Debt service",IF(T6>20,0,W6*MAX(0,MIN(20-T6+1,U6))),IF(OR(S6="Annual O&M",S6="Maintenance-only"),IF(T6>20,0,IF(O6<>"",O6,MAX(0,N(I6)+N(K6))*IF(N6<>"",N6,M6))*MAX(0,20-T6+1)),0)))),0) | AG6: =IFERROR(IF(OR(R6<>"Yes",Q6<>"ESD"),0,IF(S6="Cash capital",IF(T6<=30,IF(O6<>"",O6,MAX(0,N(J6)+N(K6))*IF(N6<>"",N6,M6)),0),IF(S6="Debt service",IF(T6>30,0,W6*MAX(0,MIN(30-T6+1,U6))),IF(OR(S6="Annual O&M",S6="Maintenance-only"),IF(T6>30,0,IF(O6<>"",O6,MAX(0,N(J6)+N(K6))*IF(N6<>"",N6,M6))*MAX(0,30-T6+1)),0)))),0) | AH6: Hydrant count from distribution LF / spacing; verify fire code and utility standards.
A7: Water wells, 1,500 gpm | B7: City | C7: water demand MGD | D7: each | E7: threshold 0.50 MGD | F7: =IF((('03_Multi_Horizon_Results'!$B$22/INPUTS!$D$50)*'12_Takeoff_Assumptions'!$B$13/1000000)>'12_Takeoff_Assumptions'!$B$16,ROUNDUP((('03_Multi_Horizon_Results'!$B$22/INPUTS!$D$50)*'12_Takeoff_Assumptions'!$B$13/1000000)/'12_Takeoff_Assumptions'!$B$16,0),0) | G7: =IF((('03_Multi_Horizon_Results'!$C$22/INPUTS!$D$50)*'12_Takeoff_Assumptions'!$B$13/1000000)>'12_Takeoff_Assumptions'!$B$16,ROUNDUP((('03_Multi_Horizon_Results'!$C$22/INPUTS!$D$50)*'12_Takeoff_Assumptions'!$B$13/1000000)/'12_Takeoff_Assumptions'!$B$16,0),0) | H7: =IF((('03_Multi_Horizon_Results'!$D$22/INPUTS!$D$50)*'12_Takeoff_Assumptions'!$B$13/1000000)>'12_Takeoff_Assumptions'!$B$16,ROUNDUP((('03_Multi_Horizon_Results'!$D$22/INPUTS!$D$50)*'12_Takeoff_Assumptions'!$B$13/1000000)/'12_Takeoff_Assumptions'!$B$16,0),0) | I7: =IF((('03_Multi_Horizon_Results'!$E$22/INPUTS!$D$50)*'12_Takeoff_Assumptions'!$B$13/1000000)>'12_Takeoff_Assumptions'!$B$16,ROUNDUP((('03_Multi_Horizon_Results'!$E$22/INPUTS!$D$50)*'12_Takeoff_Assumptions'!$B$13/1000000)/'12_Takeoff_Assumptions'!$B$16,0),0) | J7: =IF((('03_Multi_Horizon_Results'!$F$22/INPUTS!$D$50)*'12_Takeoff_Assumptions'!$B$13/1000000)>'12_Takeoff_Assumptions'!$B$16,ROUNDUP((('03_Multi_Horizon_Results'!$F$22/INPUTS!$D$50)*'12_Takeoff_Assumptions'!$B$13/1000000)/'12_Takeoff_Assumptions'!$B$16,0),0) | L7: =MAX(0,N(G7)+N(K7)) | M7: 1500000 | P7: =IFERROR(IF(O7<>"",O7,L7*IF(N7<>"",N7,M7)),0) | Q7: City | R7: No | S7: Debt service | T7: 1 | U7: 20 | V7: 0.045 | W7: =IFERROR(IF(AND(R7="Yes",S7="Debt service",U7>0),IF(V7=0,P7/U7,P7*V7/(1-(1+V7)^(-U7))),0),0) | X7: =IFERROR(IF(OR(R7<>"Yes",Q7<>"City"),0,IF(S7="Cash capital",IF(T7<=5,IF(O7<>"",O7,MAX(0,N(F7)+N(K7))*IF(N7<>"",N7,M7)),0),IF(S7="Debt service",IF(T7>5,0,W7*MAX(0,MIN(5-T7+1,U7))),IF(OR(S7="Annual O&M",S7="Maintenance-only"),IF(T7>5,0,IF(O7<>"",O7,MAX(0,N(F7)+N(K7))*IF(N7<>"",N7,M7))*MAX(0,5-T7+1)),0)))),0) | Y7: =IFERROR(IF(OR(R7<>"Yes",Q7<>"City"),0,IF(S7="Cash capital",IF(T7<=10,IF(O7<>"",O7,MAX(0,N(G7)+N(K7))*IF(N7<>"",N7,M7)),0),IF(S7="Debt service",IF(T7>10,0,W7*MAX(0,MIN(10-T7+1,U7))),IF(OR(S7="Annual O&M",S7="Maintenance-only"),IF(T7>10,0,IF(O7<>"",O7,MAX(0,N(G7)+N(K7))*IF(N7<>"",N7,M7))*MAX(0,10-T7+1)),0)))),0) | Z7: =IFERROR(IF(OR(R7<>"Yes",Q7<>"City"),0,IF(S7="Cash capital",IF(T7<=15,IF(O7<>"",O7,MAX(0,N(H7)+N(K7))*IF(N7<>"",N7,M7)),0),IF(S7="Debt service",IF(T7>15,0,W7*MAX(0,MIN(15-T7+1,U7))),IF(OR(S7="Annual O&M",S7="Maintenance-only"),IF(T7>15,0,IF(O7<>"",O7,MAX(0,N(H7)+N(K7))*IF(N7<>"",N7,M7))*MAX(0,15-T7+1)),0)))),0) | AA7: =IFERROR(IF(OR(R7<>"Yes",Q7<>"City"),0,IF(S7="Cash capital",IF(T7<=20,IF(O7<>"",O7,MAX(0,N(I7)+N(K7))*IF(N7<>"",N7,M7)),0),IF(S7="Debt service",IF(T7>20,0,W7*MAX(0,MIN(20-T7+1,U7))),IF(OR(S7="Annual O&M",S7="Maintenance-only"),IF(T7>20,0,IF(O7<>"",O7,MAX(0,N(I7)+N(K7))*IF(N7<>"",N7,M7))*MAX(0,20-T7+1)),0)))),0) | AB7: =IFERROR(IF(OR(R7<>"Yes",Q7<>"City"),0,IF(S7="Cash capital",IF(T7<=30,IF(O7<>"",O7,MAX(0,N(J7)+N(K7))*IF(N7<>"",N7,M7)),0),IF(S7="Debt service",IF(T7>30,0,W7*MAX(0,MIN(30-T7+1,U7))),IF(OR(S7="Annual O&M",S7="Maintenance-only"),IF(T7>30,0,IF(O7<>"",O7,MAX(0,N(J7)+N(K7))*IF(N7<>"",N7,M7))*MAX(0,30-T7+1)),0)))),0) | AC7: =IFERROR(IF(OR(R7<>"Yes",Q7<>"ESD"),0,IF(S7="Cash capital",IF(T7<=5,IF(O7<>"",O7,MAX(0,N(F7)+N(K7))*IF(N7<>"",N7,M7)),0),IF(S7="Debt service",IF(T7>5,0,W7*MAX(0,MIN(5-T7+1,U7))),IF(OR(S7="Annual O&M",S7="Maintenance-only"),IF(T7>5,0,IF(O7<>"",O7,MAX(0,N(F7)+N(K7))*IF(N7<>"",N7,M7))*MAX(0,5-T7+1)),0)))),0) | AD7: =IFERROR(IF(OR(R7<>"Yes",Q7<>"ESD"),0,IF(S7="Cash capital",IF(T7<=10,IF(O7<>"",O7,MAX(0,N(G7)+N(K7))*IF(N7<>"",N7,M7)),0),IF(S7="Debt service",IF(T7>10,0,W7*MAX(0,MIN(10-T7+1,U7))),IF(OR(S7="Annual O&M",S7="Maintenance-only"),IF(T7>10,0,IF(O7<>"",O7,MAX(0,N(G7)+N(K7))*IF(N7<>"",N7,M7))*MAX(0,10-T7+1)),0)))),0) | AE7: =IFERROR(IF(OR(R7<>"Yes",Q7<>"ESD"),0,IF(S7="Cash capital",IF(T7<=15,IF(O7<>"",O7,MAX(0,N(H7)+N(K7))*IF(N7<>"",N7,M7)),0),IF(S7="Debt service",IF(T7>15,0,W7*MAX(0,MIN(15-T7+1,U7))),IF(OR(S7="Annual O&M",S7="Maintenance-only"),IF(T7>15,0,IF(O7<>"",O7,MAX(0,N(H7)+N(K7))*IF(N7<>"",N7,M7))*MAX(0,15-T7+1)),0)))),0) | AF7: =IFERROR(IF(OR(R7<>"Yes",Q7<>"ESD"),0,IF(S7="Cash capital",IF(T7<=20,IF(O7<>"",O7,MAX(0,N(I7)+N(K7))*IF(N7<>"",N7,M7)),0),IF(S7="Debt service",IF(T7>20,0,W7*MAX(0,MIN(20-T7+1,U7))),IF(OR(S7="Annual O&M",S7="Maintenance-only"),IF(T7>20,0,IF(O7<>"",O7,MAX(0,N(I7)+N(K7))*IF(N7<>"",N7,M7))*MAX(0,20-T7+1)),0)))),0) | AG7: =IFERROR(IF(OR(R7<>"Yes",Q7<>"ESD"),0,IF(S7="Cash capital",IF(T7<=30,IF(O7<>"",O7,MAX(0,N(J7)+N(K7))*IF(N7<>"",N7,M7)),0),IF(S7="Debt service",IF(T7>30,0,W7*MAX(0,MIN(30-T7+1,U7))),IF(OR(S7="Annual O&M",S7="Maintenance-only"),IF(T7>30,0,IF(O7<>"",O7,MAX(0,N(J7)+N(K7))*IF(N7<>"",N7,M7))*MAX(0,30-T7+1)),0)))),0) | AH7: Demand-based planning trigger; validate with water master plan and TCEQ capacity review.
A8: Gravity sewer main, 10-inch | B8: City | C8: captured acres | D8: linear ft | E8: 300 LF/ac | F8: ='03_Multi_Horizon_Results'!$B$5*'12_Takeoff_Assumptions'!$B$4 | G8: ='03_Multi_Horizon_Results'!$C$5*'12_Takeoff_Assumptions'!$B$4 | H8: ='03_Multi_Horizon_Results'!$D$5*'12_Takeoff_Assumptions'!$B$4 | I8: ='03_Multi_Horizon_Results'!$E$5*'12_Takeoff_Assumptions'!$B$4 | J8: ='03_Multi_Horizon_Results'!$F$5*'12_Takeoff_Assumptions'!$B$4 | L8: =MAX(0,N(G8)+N(K8)) | M8: 325 | P8: =IFERROR(IF(O8<>"",O8,L8*IF(N8<>"",N8,M8)),0) | Q8: City | R8: No | S8: Debt service | T8: 1 | U8: 20 | V8: 0.045 | W8: =IFERROR(IF(AND(R8="Yes",S8="Debt service",U8>0),IF(V8=0,P8/U8,P8*V8/(1-(1+V8)^(-U8))),0),0) | X8: =IFERROR(IF(OR(R8<>"Yes",Q8<>"City"),0,IF(S8="Cash capital",IF(T8<=5,IF(O8<>"",O8,MAX(0,N(F8)+N(K8))*IF(N8<>"",N8,M8)),0),IF(S8="Debt service",IF(T8>5,0,W8*MAX(0,MIN(5-T8+1,U8))),IF(OR(S8="Annual O&M",S8="Maintenance-only"),IF(T8>5,0,IF(O8<>"",O8,MAX(0,N(F8)+N(K8))*IF(N8<>"",N8,M8))*MAX(0,5-T8+1)),0)))),0) | Y8: =IFERROR(IF(OR(R8<>"Yes",Q8<>"City"),0,IF(S8="Cash capital",IF(T8<=10,IF(O8<>"",O8,MAX(0,N(G8)+N(K8))*IF(N8<>"",N8,M8)),0),IF(S8="Debt service",IF(T8>10,0,W8*MAX(0,MIN(10-T8+1,U8))),IF(OR(S8="Annual O&M",S8="Maintenance-only"),IF(T8>10,0,IF(O8<>"",O8,MAX(0,N(G8)+N(K8))*IF(N8<>"",N8,M8))*MAX(0,10-T8+1)),0)))),0) | Z8: =IFERROR(IF(OR(R8<>"Yes",Q8<>"City"),0,IF(S8="Cash capital",IF(T8<=15,IF(O8<>"",O8,MAX(0,N(H8)+N(K8))*IF(N8<>"",N8,M8)),0),IF(S8="Debt service",IF(T8>15,0,W8*MAX(0,MIN(15-T8+1,U8))),IF(OR(S8="Annual O&M",S8="Maintenance-only"),IF(T8>15,0,IF(O8<>"",O8,MAX(0,N(H8)+N(K8))*IF(N8<>"",N8,M8))*MAX(0,15-T8+1)),0)))),0) | AA8: =IFERROR(IF(OR(R8<>"Yes",Q8<>"City"),0,IF(S8="Cash capital",IF(T8<=20,IF(O8<>"",O8,MAX(0,N(I8)+N(K8))*IF(N8<>"",N8,M8)),0),IF(S8="Debt service",IF(T8>20,0,W8*MAX(0,MIN(20-T8+1,U8))),IF(OR(S8="Annual O&M",S8="Maintenance-only"),IF(T8>20,0,IF(O8<>"",O8,MAX(0,N(I8)+N(K8))*IF(N8<>"",N8,M8))*MAX(0,20-T8+1)),0)))),0) | AB8: =IFERROR(IF(OR(R8<>"Yes",Q8<>"City"),0,IF(S8="Cash capital",IF(T8<=30,IF(O8<>"",O8,MAX(0,N(J8)+N(K8))*IF(N8<>"",N8,M8)),0),IF(S8="Debt service",IF(T8>30,0,W8*MAX(0,MIN(30-T8+1,U8))),IF(OR(S8="Annual O&M",S8="Maintenance-only"),IF(T8>30,0,IF(O8<>"",O8,MAX(0,N(J8)+N(K8))*IF(N8<>"",N8,M8))*MAX(0,30-T8+1)),0)))),0) | AC8: =IFERROR(IF(OR(R8<>"Yes",Q8<>"ESD"),0,IF(S8="Cash capital",IF(T8<=5,IF(O8<>"",O8,MAX(0,N(F8)+N(K8))*IF(N8<>"",N8,M8)),0),IF(S8="Debt service",IF(T8>5,0,W8*MAX(0,MIN(5-T8+1,U8))),IF(OR(S8="Annual O&M",S8="Maintenance-only"),IF(T8>5,0,IF(O8<>"",O8,MAX(0,N(F8)+N(K8))*IF(N8<>"",N8,M8))*MAX(0,5-T8+1)),0)))),0) | AD8: =IFERROR(IF(OR(R8<>"Yes",Q8<>"ESD"),0,IF(S8="Cash capital",IF(T8<=10,IF(O8<>"",O8,MAX(0,N(G8)+N(K8))*IF(N8<>"",N8,M8)),0),IF(S8="Debt service",IF(T8>10,0,W8*MAX(0,MIN(10-T8+1,U8))),IF(OR(S8="Annual O&M",S8="Maintenance-only"),IF(T8>10,0,IF(O8<>"",O8,MAX(0,N(G8)+N(K8))*IF(N8<>"",N8,M8))*MAX(0,10-T8+1)),0)))),0) | AE8: =IFERROR(IF(OR(R8<>"Yes",Q8<>"ESD"),0,IF(S8="Cash capital",IF(T8<=15,IF(O8<>"",O8,MAX(0,N(H8)+N(K8))*IF(N8<>"",N8,M8)),0),IF(S8="Debt service",IF(T8>15,0,W8*MAX(0,MIN(15-T8+1,U8))),IF(OR(S8="Annual O&M",S8="Maintenance-only"),IF(T8>15,0,IF(O8<>"",O8,MAX(0,N(H8)+N(K8))*IF(N8<>"",N8,M8))*MAX(0,15-T8+1)),0)))),0) | AF8: =IFERROR(IF(OR(R8<>"Yes",Q8<>"ESD"),0,IF(S8="Cash capital",IF(T8<=20,IF(O8<>"",O8,MAX(0,N(I8)+N(K8))*IF(N8<>"",N8,M8)),0),IF(S8="Debt service",IF(T8>20,0,W8*MAX(0,MIN(20-T8+1,U8))),IF(OR(S8="Annual O&M",S8="Maintenance-only"),IF(T8>20,0,IF(O8<>"",O8,MAX(0,N(I8)+N(K8))*IF(N8<>"",N8,M8))*MAX(0,20-T8+1)),0)))),0) | AG8: =IFERROR(IF(OR(R8<>"Yes",Q8<>"ESD"),0,IF(S8="Cash capital",IF(T8<=30,IF(O8<>"",O8,MAX(0,N(J8)+N(K8))*IF(N8<>"",N8,M8)),0),IF(S8="Debt service",IF(T8>30,0,W8*MAX(0,MIN(30-T8+1,U8))),IF(OR(S8="Annual O&M",S8="Maintenance-only"),IF(T8>30,0,IF(O8<>"",O8,MAX(0,N(J8)+N(K8))*IF(N8<>"",N8,M8))*MAX(0,30-T8+1)),0)))),0) | AH8: Gravity sewer planning allowance; actual basin/topography should override.
A9: Force main | B9: City | C9: captured acres | D9: linear ft | E9: 40 LF/ac | F9: ='03_Multi_Horizon_Results'!$B$5*'12_Takeoff_Assumptions'!$B$5 | G9: ='03_Multi_Horizon_Results'!$C$5*'12_Takeoff_Assumptions'!$B$5 | H9: ='03_Multi_Horizon_Results'!$D$5*'12_Takeoff_Assumptions'!$B$5 | I9: ='03_Multi_Horizon_Results'!$E$5*'12_Takeoff_Assumptions'!$B$5 | J9: ='03_Multi_Horizon_Results'!$F$5*'12_Takeoff_Assumptions'!$B$5 | L9: =MAX(0,N(G9)+N(K9)) | M9: 225 | P9: =IFERROR(IF(O9<>"",O9,L9*IF(N9<>"",N9,M9)),0) | Q9: City | R9: No | S9: Debt service | T9: 1 | U9: 20 | V9: 0.045 | W9: =IFERROR(IF(AND(R9="Yes",S9="Debt service",U9>0),IF(V9=0,P9/U9,P9*V9/(1-(1+V9)^(-U9))),0),0) | X9: =IFERROR(IF(OR(R9<>"Yes",Q9<>"City"),0,IF(S9="Cash capital",IF(T9<=5,IF(O9<>"",O9,MAX(0,N(F9)+N(K9))*IF(N9<>"",N9,M9)),0),IF(S9="Debt service",IF(T9>5,0,W9*MAX(0,MIN(5-T9+1,U9))),IF(OR(S9="Annual O&M",S9="Maintenance-only"),IF(T9>5,0,IF(O9<>"",O9,MAX(0,N(F9)+N(K9))*IF(N9<>"",N9,M9))*MAX(0,5-T9+1)),0)))),0) | Y9: =IFERROR(IF(OR(R9<>"Yes",Q9<>"City"),0,IF(S9="Cash capital",IF(T9<=10,IF(O9<>"",O9,MAX(0,N(G9)+N(K9))*IF(N9<>"",N9,M9)),0),IF(S9="Debt service",IF(T9>10,0,W9*MAX(0,MIN(10-T9+1,U9))),IF(OR(S9="Annual O&M",S9="Maintenance-only"),IF(T9>10,0,IF(O9<>"",O9,MAX(0,N(G9)+N(K9))*IF(N9<>"",N9,M9))*MAX(0,10-T9+1)),0)))),0) | Z9: =IFERROR(IF(OR(R9<>"Yes",Q9<>"City"),0,IF(S9="Cash capital",IF(T9<=15,IF(O9<>"",O9,MAX(0,N(H9)+N(K9))*IF(N9<>"",N9,M9)),0),IF(S9="Debt service",IF(T9>15,0,W9*MAX(0,MIN(15-T9+1,U9))),IF(OR(S9="Annual O&M",S9="Maintenance-only"),IF(T9>15,0,IF(O9<>"",O9,MAX(0,N(H9)+N(K9))*IF(N9<>"",N9,M9))*MAX(0,15-T9+1)),0)))),0) | AA9: =IFERROR(IF(OR(R9<>"Yes",Q9<>"City"),0,IF(S9="Cash capital",IF(T9<=20,IF(O9<>"",O9,MAX(0,N(I9)+N(K9))*IF(N9<>"",N9,M9)),0),IF(S9="Debt service",IF(T9>20,0,W9*MAX(0,MIN(20-T9+1,U9))),IF(OR(S9="Annual O&M",S9="Maintenance-only"),IF(T9>20,0,IF(O9<>"",O9,MAX(0,N(I9)+N(K9))*IF(N9<>"",N9,M9))*MAX(0,20-T9+1)),0)))),0) | AB9: =IFERROR(IF(OR(R9<>"Yes",Q9<>"City"),0,IF(S9="Cash capital",IF(T9<=30,IF(O9<>"",O9,MAX(0,N(J9)+N(K9))*IF(N9<>"",N9,M9)),0),IF(S9="Debt service",IF(T9>30,0,W9*MAX(0,MIN(30-T9+1,U9))),IF(OR(S9="Annual O&M",S9="Maintenance-only"),IF(T9>30,0,IF(O9<>"",O9,MAX(0,N(J9)+N(K9))*IF(N9<>"",N9,M9))*MAX(0,30-T9+1)),0)))),0) | AC9: =IFERROR(IF(OR(R9<>"Yes",Q9<>"ESD"),0,IF(S9="Cash capital",IF(T9<=5,IF(O9<>"",O9,MAX(0,N(F9)+N(K9))*IF(N9<>"",N9,M9)),0),IF(S9="Debt service",IF(T9>5,0,W9*MAX(0,MIN(5-T9+1,U9))),IF(OR(S9="Annual O&M",S9="Maintenance-only"),IF(T9>5,0,IF(O9<>"",O9,MAX(0,N(F9)+N(K9))*IF(N9<>"",N9,M9))*MAX(0,5-T9+1)),0)))),0) | AD9: =IFERROR(IF(OR(R9<>"Yes",Q9<>"ESD"),0,IF(S9="Cash capital",IF(T9<=10,IF(O9<>"",O9,MAX(0,N(G9)+N(K9))*IF(N9<>"",N9,M9)),0),IF(S9="Debt service",IF(T9>10,0,W9*MAX(0,MIN(10-T9+1,U9))),IF(OR(S9="Annual O&M",S9="Maintenance-only"),IF(T9>10,0,IF(O9<>"",O9,MAX(0,N(G9)+N(K9))*IF(N9<>"",N9,M9))*MAX(0,10-T9+1)),0)))),0) | AE9: =IFERROR(IF(OR(R9<>"Yes",Q9<>"ESD"),0,IF(S9="Cash capital",IF(T9<=15,IF(O9<>"",O9,MAX(0,N(H9)+N(K9))*IF(N9<>"",N9,M9)),0),IF(S9="Debt service",IF(T9>15,0,W9*MAX(0,MIN(15-T9+1,U9))),IF(OR(S9="Annual O&M",S9="Maintenance-only"),IF(T9>15,0,IF(O9<>"",O9,MAX(0,N(H9)+N(K9))*IF(N9<>"",N9,M9))*MAX(0,15-T9+1)),0)))),0) | AF9: =IFERROR(IF(OR(R9<>"Yes",Q9<>"ESD"),0,IF(S9="Cash capital",IF(T9<=20,IF(O9<>"",O9,MAX(0,N(I9)+N(K9))*IF(N9<>"",N9,M9)),0),IF(S9="Debt service",IF(T9>20,0,W9*MAX(0,MIN(20-T9+1,U9))),IF(OR(S9="Annual O&M",S9="Maintenance-only"),IF(T9>20,0,IF(O9<>"",O9,MAX(0,N(I9)+N(K9))*IF(N9<>"",N9,M9))*MAX(0,20-T9+1)),0)))),0) | AG9: =IFERROR(IF(OR(R9<>"Yes",Q9<>"ESD"),0,IF(S9="Cash capital",IF(T9<=30,IF(O9<>"",O9,MAX(0,N(J9)+N(K9))*IF(N9<>"",N9,M9)),0),IF(S9="Debt service",IF(T9>30,0,W9*MAX(0,MIN(30-T9+1,U9))),IF(OR(S9="Annual O&M",S9="Maintenance-only"),IF(T9>30,0,IF(O9<>"",O9,MAX(0,N(J9)+N(K9))*IF(N9<>"",N9,M9))*MAX(0,30-T9+1)),0)))),0) | AH9: Force-main planning allowance; actual need depends on lift-station/basin design.
A10: Lift stations | B10: City | C10: sewer demand MGD | D10: each | E10: threshold 0.25 MGD | F10: =IF((('03_Multi_Horizon_Results'!$B$22/INPUTS!$D$50)*'12_Takeoff_Assumptions'!$B$14/1000000)>'12_Takeoff_Assumptions'!$B$15,ROUNDUP((('03_Multi_Horizon_Results'!$B$22/INPUTS!$D$50)*'12_Takeoff_Assumptions'!$B$14/1000000)/'12_Takeoff_Assumptions'!$B$15,0),0) | G10: =IF((('03_Multi_Horizon_Results'!$C$22/INPUTS!$D$50)*'12_Takeoff_Assumptions'!$B$14/1000000)>'12_Takeoff_Assumptions'!$B$15,ROUNDUP((('03_Multi_Horizon_Results'!$C$22/INPUTS!$D$50)*'12_Takeoff_Assumptions'!$B$14/1000000)/'12_Takeoff_Assumptions'!$B$15,0),0) | H10: =IF((('03_Multi_Horizon_Results'!$D$22/INPUTS!$D$50)*'12_Takeoff_Assumptions'!$B$14/1000000)>'12_Takeoff_Assumptions'!$B$15,ROUNDUP((('03_Multi_Horizon_Results'!$D$22/INPUTS!$D$50)*'12_Takeoff_Assumptions'!$B$14/1000000)/'12_Takeoff_Assumptions'!$B$15,0),0) | I10: =IF((('03_Multi_Horizon_Results'!$E$22/INPUTS!$D$50)*'12_Takeoff_Assumptions'!$B$14/1000000)>'12_Takeoff_Assumptions'!$B$15,ROUNDUP((('03_Multi_Horizon_Results'!$E$22/INPUTS!$D$50)*'12_Takeoff_Assumptions'!$B$14/1000000)/'12_Takeoff_Assumptions'!$B$15,0),0) | J10: =IF((('03_Multi_Horizon_Results'!$F$22/INPUTS!$D$50)*'12_Takeoff_Assumptions'!$B$14/1000000)>'12_Takeoff_Assumptions'!$B$15,ROUNDUP((('03_Multi_Horizon_Results'!$F$22/INPUTS!$D$50)*'12_Takeoff_Assumptions'!$B$14/1000000)/'12_Takeoff_Assumptions'!$B$15,0),0) | L10: =MAX(0,N(G10)+N(K10)) | M10: 1250000 | P10: =IFERROR(IF(O10<>"",O10,L10*IF(N10<>"",N10,M10)),0) | Q10: City | R10: No | S10: Debt service | T10: 1 | U10: 20 | V10: 0.045 | W10: =IFERROR(IF(AND(R10="Yes",S10="Debt service",U10>0),IF(V10=0,P10/U10,P10*V10/(1-(1+V10)^(-U10))),0),0) | X10: =IFERROR(IF(OR(R10<>"Yes",Q10<>"City"),0,IF(S10="Cash capital",IF(T10<=5,IF(O10<>"",O10,MAX(0,N(F10)+N(K10))*IF(N10<>"",N10,M10)),0),IF(S10="Debt service",IF(T10>5,0,W10*MAX(0,MIN(5-T10+1,U10))),IF(OR(S10="Annual O&M",S10="Maintenance-only"),IF(T10>5,0,IF(O10<>"",O10,MAX(0,N(F10)+N(K10))*IF(N10<>"",N10,M10))*MAX(0,5-T10+1)),0)))),0) | Y10: =IFERROR(IF(OR(R10<>"Yes",Q10<>"City"),0,IF(S10="Cash capital",IF(T10<=10,IF(O10<>"",O10,MAX(0,N(G10)+N(K10))*IF(N10<>"",N10,M10)),0),IF(S10="Debt service",IF(T10>10,0,W10*MAX(0,MIN(10-T10+1,U10))),IF(OR(S10="Annual O&M",S10="Maintenance-only"),IF(T10>10,0,IF(O10<>"",O10,MAX(0,N(G10)+N(K10))*IF(N10<>"",N10,M10))*MAX(0,10-T10+1)),0)))),0) | Z10: =IFERROR(IF(OR(R10<>"Yes",Q10<>"City"),0,IF(S10="Cash capital",IF(T10<=15,IF(O10<>"",O10,MAX(0,N(H10)+N(K10))*IF(N10<>"",N10,M10)),0),IF(S10="Debt service",IF(T10>15,0,W10*MAX(0,MIN(15-T10+1,U10))),IF(OR(S10="Annual O&M",S10="Maintenance-only"),IF(T10>15,0,IF(O10<>"",O10,MAX(0,N(H10)+N(K10))*IF(N10<>"",N10,M10))*MAX(0,15-T10+1)),0)))),0) | AA10: =IFERROR(IF(OR(R10<>"Yes",Q10<>"City"),0,IF(S10="Cash capital",IF(T10<=20,IF(O10<>"",O10,MAX(0,N(I10)+N(K10))*IF(N10<>"",N10,M10)),0),IF(S10="Debt service",IF(T10>20,0,W10*MAX(0,MIN(20-T10+1,U10))),IF(OR(S10="Annual O&M",S10="Maintenance-only"),IF(T10>20,0,IF(O10<>"",O10,MAX(0,N(I10)+N(K10))*IF(N10<>"",N10,M10))*MAX(0,20-T10+1)),0)))),0) | AB10: =IFERROR(IF(OR(R10<>"Yes",Q10<>"City"),0,IF(S10="Cash capital",IF(T10<=30,IF(O10<>"",O10,MAX(0,N(J10)+N(K10))*IF(N10<>"",N10,M10)),0),IF(S10="Debt service",IF(T10>30,0,W10*MAX(0,MIN(30-T10+1,U10))),IF(OR(S10="Annual O&M",S10="Maintenance-only"),IF(T10>30,0,IF(O10<>"",O10,MAX(0,N(J10)+N(K10))*IF(N10<>"",N10,M10))*MAX(0,30-T10+1)),0)))),0) | AC10: =IFERROR(IF(OR(R10<>"Yes",Q10<>"ESD"),0,IF(S10="Cash capital",IF(T10<=5,IF(O10<>"",O10,MAX(0,N(F10)+N(K10))*IF(N10<>"",N10,M10)),0),IF(S10="Debt service",IF(T10>5,0,W10*MAX(0,MIN(5-T10+1,U10))),IF(OR(S10="Annual O&M",S10="Maintenance-only"),IF(T10>5,0,IF(O10<>"",O10,MAX(0,N(F10)+N(K10))*IF(N10<>"",N10,M10))*MAX(0,5-T10+1)),0)))),0) | AD10: =IFERROR(IF(OR(R10<>"Yes",Q10<>"ESD"),0,IF(S10="Cash capital",IF(T10<=10,IF(O10<>"",O10,MAX(0,N(G10)+N(K10))*IF(N10<>"",N10,M10)),0),IF(S10="Debt service",IF(T10>10,0,W10*MAX(0,MIN(10-T10+1,U10))),IF(OR(S10="Annual O&M",S10="Maintenance-only"),IF(T10>10,0,IF(O10<>"",O10,MAX(0,N(G10)+N(K10))*IF(N10<>"",N10,M10))*MAX(0,10-T10+1)),0)))),0) | AE10: =IFERROR(IF(OR(R10<>"Yes",Q10<>"ESD"),0,IF(S10="Cash capital",IF(T10<=15,IF(O10<>"",O10,MAX(0,N(H10)+N(K10))*IF(N10<>"",N10,M10)),0),IF(S10="Debt service",IF(T10>15,0,W10*MAX(0,MIN(15-T10+1,U10))),IF(OR(S10="Annual O&M",S10="Maintenance-only"),IF(T10>15,0,IF(O10<>"",O10,MAX(0,N(H10)+N(K10))*IF(N10<>"",N10,M10))*MAX(0,15-T10+1)),0)))),0) | AF10: =IFERROR(IF(OR(R10<>"Yes",Q10<>"ESD"),0,IF(S10="Cash capital",IF(T10<=20,IF(O10<>"",O10,MAX(0,N(I10)+N(K10))*IF(N10<>"",N10,M10)),0),IF(S10="Debt service",IF(T10>20,0,W10*MAX(0,MIN(20-T10+1,U10))),IF(OR(S10="Annual O&M",S10="Maintenance-only"),IF(T10>20,0,IF(O10<>"",O10,MAX(0,N(I10)+N(K10))*IF(N10<>"",N10,M10))*MAX(0,20-T10+1)),0)))),0) | AG10: =IFERROR(IF(OR(R10<>"Yes",Q10<>"ESD"),0,IF(S10="Cash capital",IF(T10<=30,IF(O10<>"",O10,MAX(0,N(J10)+N(K10))*IF(N10<>"",N10,M10)),0),IF(S10="Debt service",IF(T10>30,0,W10*MAX(0,MIN(30-T10+1,U10))),IF(OR(S10="Annual O&M",S10="Maintenance-only"),IF(T10>30,0,IF(O10<>"",O10,MAX(0,N(J10)+N(K10))*IF(N10<>"",N10,M10))*MAX(0,30-T10+1)),0)))),0) | AH10: Planning trigger only; topography and basin engineer review required.
A11: WWTP expansion capacity | B11: City | C11: sewer demand MGD | D11: MGD | E11: 250 gpd/LUE | F11: =(('03_Multi_Horizon_Results'!$B$22/INPUTS!$D$50)*'12_Takeoff_Assumptions'!$B$14/1000000) | G11: =(('03_Multi_Horizon_Results'!$C$22/INPUTS!$D$50)*'12_Takeoff_Assumptions'!$B$14/1000000) | H11: =(('03_Multi_Horizon_Results'!$D$22/INPUTS!$D$50)*'12_Takeoff_Assumptions'!$B$14/1000000) | I11: =(('03_Multi_Horizon_Results'!$E$22/INPUTS!$D$50)*'12_Takeoff_Assumptions'!$B$14/1000000) | J11: =(('03_Multi_Horizon_Results'!$F$22/INPUTS!$D$50)*'12_Takeoff_Assumptions'!$B$14/1000000) | L11: =MAX(0,N(G11)+N(K11)) | M11: 6000000 | P11: =IFERROR(IF(O11<>"",O11,L11*IF(N11<>"",N11,M11)),0) | Q11: City | R11: No | S11: Debt service | T11: 1 | U11: 20 | V11: 0.045 | W11: =IFERROR(IF(AND(R11="Yes",S11="Debt service",U11>0),IF(V11=0,P11/U11,P11*V11/(1-(1+V11)^(-U11))),0),0) | X11: =IFERROR(IF(OR(R11<>"Yes",Q11<>"City"),0,IF(S11="Cash capital",IF(T11<=5,IF(O11<>"",O11,MAX(0,N(F11)+N(K11))*IF(N11<>"",N11,M11)),0),IF(S11="Debt service",IF(T11>5,0,W11*MAX(0,MIN(5-T11+1,U11))),IF(OR(S11="Annual O&M",S11="Maintenance-only"),IF(T11>5,0,IF(O11<>"",O11,MAX(0,N(F11)+N(K11))*IF(N11<>"",N11,M11))*MAX(0,5-T11+1)),0)))),0) | Y11: =IFERROR(IF(OR(R11<>"Yes",Q11<>"City"),0,IF(S11="Cash capital",IF(T11<=10,IF(O11<>"",O11,MAX(0,N(G11)+N(K11))*IF(N11<>"",N11,M11)),0),IF(S11="Debt service",IF(T11>10,0,W11*MAX(0,MIN(10-T11+1,U11))),IF(OR(S11="Annual O&M",S11="Maintenance-only"),IF(T11>10,0,IF(O11<>"",O11,MAX(0,N(G11)+N(K11))*IF(N11<>"",N11,M11))*MAX(0,10-T11+1)),0)))),0) | Z11: =IFERROR(IF(OR(R11<>"Yes",Q11<>"City"),0,IF(S11="Cash capital",IF(T11<=15,IF(O11<>"",O11,MAX(0,N(H11)+N(K11))*IF(N11<>"",N11,M11)),0),IF(S11="Debt service",IF(T11>15,0,W11*MAX(0,MIN(15-T11+1,U11))),IF(OR(S11="Annual O&M",S11="Maintenance-only"),IF(T11>15,0,IF(O11<>"",O11,MAX(0,N(H11)+N(K11))*IF(N11<>"",N11,M11))*MAX(0,15-T11+1)),0)))),0) | AA11: =IFERROR(IF(OR(R11<>"Yes",Q11<>"City"),0,IF(S11="Cash capital",IF(T11<=20,IF(O11<>"",O11,MAX(0,N(I11)+N(K11))*IF(N11<>"",N11,M11)),0),IF(S11="Debt service",IF(T11>20,0,W11*MAX(0,MIN(20-T11+1,U11))),IF(OR(S11="Annual O&M",S11="Maintenance-only"),IF(T11>20,0,IF(O11<>"",O11,MAX(0,N(I11)+N(K11))*IF(N11<>"",N11,M11))*MAX(0,20-T11+1)),0)))),0) | AB11: =IFERROR(IF(OR(R11<>"Yes",Q11<>"City"),0,IF(S11="Cash capital",IF(T11<=30,IF(O11<>"",O11,MAX(0,N(J11)+N(K11))*IF(N11<>"",N11,M11)),0),IF(S11="Debt service",IF(T11>30,0,W11*MAX(0,MIN(30-T11+1,U11))),IF(OR(S11="Annual O&M",S11="Maintenance-only"),IF(T11>30,0,IF(O11<>"",O11,MAX(0,N(J11)+N(K11))*IF(N11<>"",N11,M11))*MAX(0,30-T11+1)),0)))),0) | AC11: =IFERROR(IF(OR(R11<>"Yes",Q11<>"ESD"),0,IF(S11="Cash capital",IF(T11<=5,IF(O11<>"",O11,MAX(0,N(F11)+N(K11))*IF(N11<>"",N11,M11)),0),IF(S11="Debt service",IF(T11>5,0,W11*MAX(0,MIN(5-T11+1,U11))),IF(OR(S11="Annual O&M",S11="Maintenance-only"),IF(T11>5,0,IF(O11<>"",O11,MAX(0,N(F11)+N(K11))*IF(N11<>"",N11,M11))*MAX(0,5-T11+1)),0)))),0) | AD11: =IFERROR(IF(OR(R11<>"Yes",Q11<>"ESD"),0,IF(S11="Cash capital",IF(T11<=10,IF(O11<>"",O11,MAX(0,N(G11)+N(K11))*IF(N11<>"",N11,M11)),0),IF(S11="Debt service",IF(T11>10,0,W11*MAX(0,MIN(10-T11+1,U11))),IF(OR(S11="Annual O&M",S11="Maintenance-only"),IF(T11>10,0,IF(O11<>"",O11,MAX(0,N(G11)+N(K11))*IF(N11<>"",N11,M11))*MAX(0,10-T11+1)),0)))),0) | AE11: =IFERROR(IF(OR(R11<>"Yes",Q11<>"ESD"),0,IF(S11="Cash capital",IF(T11<=15,IF(O11<>"",O11,MAX(0,N(H11)+N(K11))*IF(N11<>"",N11,M11)),0),IF(S11="Debt service",IF(T11>15,0,W11*MAX(0,MIN(15-T11+1,U11))),IF(OR(S11="Annual O&M",S11="Maintenance-only"),IF(T11>15,0,IF(O11<>"",O11,MAX(0,N(H11)+N(K11))*IF(N11<>"",N11,M11))*MAX(0,15-T11+1)),0)))),0) | AF11: =IFERROR(IF(OR(R11<>"Yes",Q11<>"ESD"),0,IF(S11="Cash capital",IF(T11<=20,IF(O11<>"",O11,MAX(0,N(I11)+N(K11))*IF(N11<>"",N11,M11)),0),IF(S11="Debt service",IF(T11>20,0,W11*MAX(0,MIN(20-T11+1,U11))),IF(OR(S11="Annual O&M",S11="Maintenance-only"),IF(T11>20,0,IF(O11<>"",O11,MAX(0,N(I11)+N(K11))*IF(N11<>"",N11,M11))*MAX(0,20-T11+1)),0)))),0) | AG11: =IFERROR(IF(OR(R11<>"Yes",Q11<>"ESD"),0,IF(S11="Cash capital",IF(T11<=30,IF(O11<>"",O11,MAX(0,N(J11)+N(K11))*IF(N11<>"",N11,M11)),0),IF(S11="Debt service",IF(T11>30,0,W11*MAX(0,MIN(30-T11+1,U11))),IF(OR(S11="Annual O&M",S11="Maintenance-only"),IF(T11>30,0,IF(O11<>"",O11,MAX(0,N(J11)+N(K11))*IF(N11<>"",N11,M11))*MAX(0,30-T11+1)),0)))),0) | AH11: Shows estimated sewer demand capacity exposure, not an engineering design directive.
A12: Collector street | B12: City | C12: captured acres | D12: lane-miles | E12: 0.02 lane-mi/ac | F12: ='03_Multi_Horizon_Results'!$B$5*'12_Takeoff_Assumptions'!$B$7 | G12: ='03_Multi_Horizon_Results'!$C$5*'12_Takeoff_Assumptions'!$B$7 | H12: ='03_Multi_Horizon_Results'!$D$5*'12_Takeoff_Assumptions'!$B$7 | I12: ='03_Multi_Horizon_Results'!$E$5*'12_Takeoff_Assumptions'!$B$7 | J12: ='03_Multi_Horizon_Results'!$F$5*'12_Takeoff_Assumptions'!$B$7 | L12: =MAX(0,N(G12)+N(K12)) | M12: 750000 | P12: =IFERROR(IF(O12<>"",O12,L12*IF(N12<>"",N12,M12)),0) | Q12: City | R12: No | S12: Debt service | T12: 1 | U12: 20 | V12: 0.045 | W12: =IFERROR(IF(AND(R12="Yes",S12="Debt service",U12>0),IF(V12=0,P12/U12,P12*V12/(1-(1+V12)^(-U12))),0),0) | X12: =IFERROR(IF(OR(R12<>"Yes",Q12<>"City"),0,IF(S12="Cash capital",IF(T12<=5,IF(O12<>"",O12,MAX(0,N(F12)+N(K12))*IF(N12<>"",N12,M12)),0),IF(S12="Debt service",IF(T12>5,0,W12*MAX(0,MIN(5-T12+1,U12))),IF(OR(S12="Annual O&M",S12="Maintenance-only"),IF(T12>5,0,IF(O12<>"",O12,MAX(0,N(F12)+N(K12))*IF(N12<>"",N12,M12))*MAX(0,5-T12+1)),0)))),0) | Y12: =IFERROR(IF(OR(R12<>"Yes",Q12<>"City"),0,IF(S12="Cash capital",IF(T12<=10,IF(O12<>"",O12,MAX(0,N(G12)+N(K12))*IF(N12<>"",N12,M12)),0),IF(S12="Debt service",IF(T12>10,0,W12*MAX(0,MIN(10-T12+1,U12))),IF(OR(S12="Annual O&M",S12="Maintenance-only"),IF(T12>10,0,IF(O12<>"",O12,MAX(0,N(G12)+N(K12))*IF(N12<>"",N12,M12))*MAX(0,10-T12+1)),0)))),0) | Z12: =IFERROR(IF(OR(R12<>"Yes",Q12<>"City"),0,IF(S12="Cash capital",IF(T12<=15,IF(O12<>"",O12,MAX(0,N(H12)+N(K12))*IF(N12<>"",N12,M12)),0),IF(S12="Debt service",IF(T12>15,0,W12*MAX(0,MIN(15-T12+1,U12))),IF(OR(S12="Annual O&M",S12="Maintenance-only"),IF(T12>15,0,IF(O12<>"",O12,MAX(0,N(H12)+N(K12))*IF(N12<>"",N12,M12))*MAX(0,15-T12+1)),0)))),0) | AA12: =IFERROR(IF(OR(R12<>"Yes",Q12<>"City"),0,IF(S12="Cash capital",IF(T12<=20,IF(O12<>"",O12,MAX(0,N(I12)+N(K12))*IF(N12<>"",N12,M12)),0),IF(S12="Debt service",IF(T12>20,0,W12*MAX(0,MIN(20-T12+1,U12))),IF(OR(S12="Annual O&M",S12="Maintenance-only"),IF(T12>20,0,IF(O12<>"",O12,MAX(0,N(I12)+N(K12))*IF(N12<>"",N12,M12))*MAX(0,20-T12+1)),0)))),0) | AB12: =IFERROR(IF(OR(R12<>"Yes",Q12<>"City"),0,IF(S12="Cash capital",IF(T12<=30,IF(O12<>"",O12,MAX(0,N(J12)+N(K12))*IF(N12<>"",N12,M12)),0),IF(S12="Debt service",IF(T12>30,0,W12*MAX(0,MIN(30-T12+1,U12))),IF(OR(S12="Annual O&M",S12="Maintenance-only"),IF(T12>30,0,IF(O12<>"",O12,MAX(0,N(J12)+N(K12))*IF(N12<>"",N12,M12))*MAX(0,30-T12+1)),0)))),0) | AC12: =IFERROR(IF(OR(R12<>"Yes",Q12<>"ESD"),0,IF(S12="Cash capital",IF(T12<=5,IF(O12<>"",O12,MAX(0,N(F12)+N(K12))*IF(N12<>"",N12,M12)),0),IF(S12="Debt service",IF(T12>5,0,W12*MAX(0,MIN(5-T12+1,U12))),IF(OR(S12="Annual O&M",S12="Maintenance-only"),IF(T12>5,0,IF(O12<>"",O12,MAX(0,N(F12)+N(K12))*IF(N12<>"",N12,M12))*MAX(0,5-T12+1)),0)))),0) | AD12: =IFERROR(IF(OR(R12<>"Yes",Q12<>"ESD"),0,IF(S12="Cash capital",IF(T12<=10,IF(O12<>"",O12,MAX(0,N(G12)+N(K12))*IF(N12<>"",N12,M12)),0),IF(S12="Debt service",IF(T12>10,0,W12*MAX(0,MIN(10-T12+1,U12))),IF(OR(S12="Annual O&M",S12="Maintenance-only"),IF(T12>10,0,IF(O12<>"",O12,MAX(0,N(G12)+N(K12))*IF(N12<>"",N12,M12))*MAX(0,10-T12+1)),0)))),0) | AE12: =IFERROR(IF(OR(R12<>"Yes",Q12<>"ESD"),0,IF(S12="Cash capital",IF(T12<=15,IF(O12<>"",O12,MAX(0,N(H12)+N(K12))*IF(N12<>"",N12,M12)),0),IF(S12="Debt service",IF(T12>15,0,W12*MAX(0,MIN(15-T12+1,U12))),IF(OR(S12="Annual O&M",S12="Maintenance-only"),IF(T12>15,0,IF(O12<>"",O12,MAX(0,N(H12)+N(K12))*IF(N12<>"",N12,M12))*MAX(0,15-T12+1)),0)))),0) | AF12: =IFERROR(IF(OR(R12<>"Yes",Q12<>"ESD"),0,IF(S12="Cash capital",IF(T12<=20,IF(O12<>"",O12,MAX(0,N(I12)+N(K12))*IF(N12<>"",N12,M12)),0),IF(S12="Debt service",IF(T12>20,0,W12*MAX(0,MIN(20-T12+1,U12))),IF(OR(S12="Annual O&M",S12="Maintenance-only"),IF(T12>20,0,IF(O12<>"",O12,MAX(0,N(I12)+N(K12))*IF(N12<>"",N12,M12))*MAX(0,20-T12+1)),0)))),0) | AG12: =IFERROR(IF(OR(R12<>"Yes",Q12<>"ESD"),0,IF(S12="Cash capital",IF(T12<=30,IF(O12<>"",O12,MAX(0,N(J12)+N(K12))*IF(N12<>"",N12,M12)),0),IF(S12="Debt service",IF(T12>30,0,W12*MAX(0,MIN(30-T12+1,U12))),IF(OR(S12="Annual O&M",S12="Maintenance-only"),IF(T12>30,0,IF(O12<>"",O12,MAX(0,N(J12)+N(K12))*IF(N12<>"",N12,M12))*MAX(0,30-T12+1)),0)))),0) | AH12: Thoroughfare planning allowance; actual route/section should override.
A13: Local street | B13: City | C13: captured acres | D13: lane-miles | E13: 120 centerline LF/ac × 2 lanes | F13: =('03_Multi_Horizon_Results'!$B$5*'12_Takeoff_Assumptions'!$B$6/5280)*'12_Takeoff_Assumptions'!$B$8 | G13: =('03_Multi_Horizon_Results'!$C$5*'12_Takeoff_Assumptions'!$B$6/5280)*'12_Takeoff_Assumptions'!$B$8 | H13: =('03_Multi_Horizon_Results'!$D$5*'12_Takeoff_Assumptions'!$B$6/5280)*'12_Takeoff_Assumptions'!$B$8 | I13: =('03_Multi_Horizon_Results'!$E$5*'12_Takeoff_Assumptions'!$B$6/5280)*'12_Takeoff_Assumptions'!$B$8 | J13: =('03_Multi_Horizon_Results'!$F$5*'12_Takeoff_Assumptions'!$B$6/5280)*'12_Takeoff_Assumptions'!$B$8 | L13: =MAX(0,N(G13)+N(K13)) | M13: 600000 | P13: =IFERROR(IF(O13<>"",O13,L13*IF(N13<>"",N13,M13)),0) | Q13: City | R13: No | S13: Debt service | T13: 1 | U13: 20 | V13: 0.045 | W13: =IFERROR(IF(AND(R13="Yes",S13="Debt service",U13>0),IF(V13=0,P13/U13,P13*V13/(1-(1+V13)^(-U13))),0),0) | X13: =IFERROR(IF(OR(R13<>"Yes",Q13<>"City"),0,IF(S13="Cash capital",IF(T13<=5,IF(O13<>"",O13,MAX(0,N(F13)+N(K13))*IF(N13<>"",N13,M13)),0),IF(S13="Debt service",IF(T13>5,0,W13*MAX(0,MIN(5-T13+1,U13))),IF(OR(S13="Annual O&M",S13="Maintenance-only"),IF(T13>5,0,IF(O13<>"",O13,MAX(0,N(F13)+N(K13))*IF(N13<>"",N13,M13))*MAX(0,5-T13+1)),0)))),0) | Y13: =IFERROR(IF(OR(R13<>"Yes",Q13<>"City"),0,IF(S13="Cash capital",IF(T13<=10,IF(O13<>"",O13,MAX(0,N(G13)+N(K13))*IF(N13<>"",N13,M13)),0),IF(S13="Debt service",IF(T13>10,0,W13*MAX(0,MIN(10-T13+1,U13))),IF(OR(S13="Annual O&M",S13="Maintenance-only"),IF(T13>10,0,IF(O13<>"",O13,MAX(0,N(G13)+N(K13))*IF(N13<>"",N13,M13))*MAX(0,10-T13+1)),0)))),0) | Z13: =IFERROR(IF(OR(R13<>"Yes",Q13<>"City"),0,IF(S13="Cash capital",IF(T13<=15,IF(O13<>"",O13,MAX(0,N(H13)+N(K13))*IF(N13<>"",N13,M13)),0),IF(S13="Debt service",IF(T13>15,0,W13*MAX(0,MIN(15-T13+1,U13))),IF(OR(S13="Annual O&M",S13="Maintenance-only"),IF(T13>15,0,IF(O13<>"",O13,MAX(0,N(H13)+N(K13))*IF(N13<>"",N13,M13))*MAX(0,15-T13+1)),0)))),0) | AA13: =IFERROR(IF(OR(R13<>"Yes",Q13<>"City"),0,IF(S13="Cash capital",IF(T13<=20,IF(O13<>"",O13,MAX(0,N(I13)+N(K13))*IF(N13<>"",N13,M13)),0),IF(S13="Debt service",IF(T13>20,0,W13*MAX(0,MIN(20-T13+1,U13))),IF(OR(S13="Annual O&M",S13="Maintenance-only"),IF(T13>20,0,IF(O13<>"",O13,MAX(0,N(I13)+N(K13))*IF(N13<>"",N13,M13))*MAX(0,20-T13+1)),0)))),0) | AB13: =IFERROR(IF(OR(R13<>"Yes",Q13<>"City"),0,IF(S13="Cash capital",IF(T13<=30,IF(O13<>"",O13,MAX(0,N(J13)+N(K13))*IF(N13<>"",N13,M13)),0),IF(S13="Debt service",IF(T13>30,0,W13*MAX(0,MIN(30-T13+1,U13))),IF(OR(S13="Annual O&M",S13="Maintenance-only"),IF(T13>30,0,IF(O13<>"",O13,MAX(0,N(J13)+N(K13))*IF(N13<>"",N13,M13))*MAX(0,30-T13+1)),0)))),0) | AC13: =IFERROR(IF(OR(R13<>"Yes",Q13<>"ESD"),0,IF(S13="Cash capital",IF(T13<=5,IF(O13<>"",O13,MAX(0,N(F13)+N(K13))*IF(N13<>"",N13,M13)),0),IF(S13="Debt service",IF(T13>5,0,W13*MAX(0,MIN(5-T13+1,U13))),IF(OR(S13="Annual O&M",S13="Maintenance-only"),IF(T13>5,0,IF(O13<>"",O13,MAX(0,N(F13)+N(K13))*IF(N13<>"",N13,M13))*MAX(0,5-T13+1)),0)))),0) | AD13: =IFERROR(IF(OR(R13<>"Yes",Q13<>"ESD"),0,IF(S13="Cash capital",IF(T13<=10,IF(O13<>"",O13,MAX(0,N(G13)+N(K13))*IF(N13<>"",N13,M13)),0),IF(S13="Debt service",IF(T13>10,0,W13*MAX(0,MIN(10-T13+1,U13))),IF(OR(S13="Annual O&M",S13="Maintenance-only"),IF(T13>10,0,IF(O13<>"",O13,MAX(0,N(G13)+N(K13))*IF(N13<>"",N13,M13))*MAX(0,10-T13+1)),0)))),0) | AE13: =IFERROR(IF(OR(R13<>"Yes",Q13<>"ESD"),0,IF(S13="Cash capital",IF(T13<=15,IF(O13<>"",O13,MAX(0,N(H13)+N(K13))*IF(N13<>"",N13,M13)),0),IF(S13="Debt service",IF(T13>15,0,W13*MAX(0,MIN(15-T13+1,U13))),IF(OR(S13="Annual O&M",S13="Maintenance-only"),IF(T13>15,0,IF(O13<>"",O13,MAX(0,N(H13)+N(K13))*IF(N13<>"",N13,M13))*MAX(0,15-T13+1)),0)))),0) | AF13: =IFERROR(IF(OR(R13<>"Yes",Q13<>"ESD"),0,IF(S13="Cash capital",IF(T13<=20,IF(O13<>"",O13,MAX(0,N(I13)+N(K13))*IF(N13<>"",N13,M13)),0),IF(S13="Debt service",IF(T13>20,0,W13*MAX(0,MIN(20-T13+1,U13))),IF(OR(S13="Annual O&M",S13="Maintenance-only"),IF(T13>20,0,IF(O13<>"",O13,MAX(0,N(I13)+N(K13))*IF(N13<>"",N13,M13))*MAX(0,20-T13+1)),0)))),0) | AG13: =IFERROR(IF(OR(R13<>"Yes",Q13<>"ESD"),0,IF(S13="Cash capital",IF(T13<=30,IF(O13<>"",O13,MAX(0,N(J13)+N(K13))*IF(N13<>"",N13,M13)),0),IF(S13="Debt service",IF(T13>30,0,W13*MAX(0,MIN(30-T13+1,U13))),IF(OR(S13="Annual O&M",S13="Maintenance-only"),IF(T13>30,0,IF(O13<>"",O13,MAX(0,N(J13)+N(K13))*IF(N13<>"",N13,M13))*MAX(0,30-T13+1)),0)))),0) | AH13: Local street lane-mile takeoff; actual plat should override.
A14: Sidewalk / trail | B14: City | C14: captured acres | D14: linear ft | E14: 300 LF/ac | F14: ='03_Multi_Horizon_Results'!$B$5*'12_Takeoff_Assumptions'!$B$24 | G14: ='03_Multi_Horizon_Results'!$C$5*'12_Takeoff_Assumptions'!$B$24 | H14: ='03_Multi_Horizon_Results'!$D$5*'12_Takeoff_Assumptions'!$B$24 | I14: ='03_Multi_Horizon_Results'!$E$5*'12_Takeoff_Assumptions'!$B$24 | J14: ='03_Multi_Horizon_Results'!$F$5*'12_Takeoff_Assumptions'!$B$24 | L14: =MAX(0,N(G14)+N(K14)) | M14: 75 | P14: =IFERROR(IF(O14<>"",O14,L14*IF(N14<>"",N14,M14)),0) | Q14: City | R14: No | S14: Debt service | T14: 1 | U14: 20 | V14: 0.045 | W14: =IFERROR(IF(AND(R14="Yes",S14="Debt service",U14>0),IF(V14=0,P14/U14,P14*V14/(1-(1+V14)^(-U14))),0),0) | X14: =IFERROR(IF(OR(R14<>"Yes",Q14<>"City"),0,IF(S14="Cash capital",IF(T14<=5,IF(O14<>"",O14,MAX(0,N(F14)+N(K14))*IF(N14<>"",N14,M14)),0),IF(S14="Debt service",IF(T14>5,0,W14*MAX(0,MIN(5-T14+1,U14))),IF(OR(S14="Annual O&M",S14="Maintenance-only"),IF(T14>5,0,IF(O14<>"",O14,MAX(0,N(F14)+N(K14))*IF(N14<>"",N14,M14))*MAX(0,5-T14+1)),0)))),0) | Y14: =IFERROR(IF(OR(R14<>"Yes",Q14<>"City"),0,IF(S14="Cash capital",IF(T14<=10,IF(O14<>"",O14,MAX(0,N(G14)+N(K14))*IF(N14<>"",N14,M14)),0),IF(S14="Debt service",IF(T14>10,0,W14*MAX(0,MIN(10-T14+1,U14))),IF(OR(S14="Annual O&M",S14="Maintenance-only"),IF(T14>10,0,IF(O14<>"",O14,MAX(0,N(G14)+N(K14))*IF(N14<>"",N14,M14))*MAX(0,10-T14+1)),0)))),0) | Z14: =IFERROR(IF(OR(R14<>"Yes",Q14<>"City"),0,IF(S14="Cash capital",IF(T14<=15,IF(O14<>"",O14,MAX(0,N(H14)+N(K14))*IF(N14<>"",N14,M14)),0),IF(S14="Debt service",IF(T14>15,0,W14*MAX(0,MIN(15-T14+1,U14))),IF(OR(S14="Annual O&M",S14="Maintenance-only"),IF(T14>15,0,IF(O14<>"",O14,MAX(0,N(H14)+N(K14))*IF(N14<>"",N14,M14))*MAX(0,15-T14+1)),0)))),0) | AA14: =IFERROR(IF(OR(R14<>"Yes",Q14<>"City"),0,IF(S14="Cash capital",IF(T14<=20,IF(O14<>"",O14,MAX(0,N(I14)+N(K14))*IF(N14<>"",N14,M14)),0),IF(S14="Debt service",IF(T14>20,0,W14*MAX(0,MIN(20-T14+1,U14))),IF(OR(S14="Annual O&M",S14="Maintenance-only"),IF(T14>20,0,IF(O14<>"",O14,MAX(0,N(I14)+N(K14))*IF(N14<>"",N14,M14))*MAX(0,20-T14+1)),0)))),0) | AB14: =IFERROR(IF(OR(R14<>"Yes",Q14<>"City"),0,IF(S14="Cash capital",IF(T14<=30,IF(O14<>"",O14,MAX(0,N(J14)+N(K14))*IF(N14<>"",N14,M14)),0),IF(S14="Debt service",IF(T14>30,0,W14*MAX(0,MIN(30-T14+1,U14))),IF(OR(S14="Annual O&M",S14="Maintenance-only"),IF(T14>30,0,IF(O14<>"",O14,MAX(0,N(J14)+N(K14))*IF(N14<>"",N14,M14))*MAX(0,30-T14+1)),0)))),0) | AC14: =IFERROR(IF(OR(R14<>"Yes",Q14<>"ESD"),0,IF(S14="Cash capital",IF(T14<=5,IF(O14<>"",O14,MAX(0,N(F14)+N(K14))*IF(N14<>"",N14,M14)),0),IF(S14="Debt service",IF(T14>5,0,W14*MAX(0,MIN(5-T14+1,U14))),IF(OR(S14="Annual O&M",S14="Maintenance-only"),IF(T14>5,0,IF(O14<>"",O14,MAX(0,N(F14)+N(K14))*IF(N14<>"",N14,M14))*MAX(0,5-T14+1)),0)))),0) | AD14: =IFERROR(IF(OR(R14<>"Yes",Q14<>"ESD"),0,IF(S14="Cash capital",IF(T14<=10,IF(O14<>"",O14,MAX(0,N(G14)+N(K14))*IF(N14<>"",N14,M14)),0),IF(S14="Debt service",IF(T14>10,0,W14*MAX(0,MIN(10-T14+1,U14))),IF(OR(S14="Annual O&M",S14="Maintenance-only"),IF(T14>10,0,IF(O14<>"",O14,MAX(0,N(G14)+N(K14))*IF(N14<>"",N14,M14))*MAX(0,10-T14+1)),0)))),0) | AE14: =IFERROR(IF(OR(R14<>"Yes",Q14<>"ESD"),0,IF(S14="Cash capital",IF(T14<=15,IF(O14<>"",O14,MAX(0,N(H14)+N(K14))*IF(N14<>"",N14,M14)),0),IF(S14="Debt service",IF(T14>15,0,W14*MAX(0,MIN(15-T14+1,U14))),IF(OR(S14="Annual O&M",S14="Maintenance-only"),IF(T14>15,0,IF(O14<>"",O14,MAX(0,N(H14)+N(K14))*IF(N14<>"",N14,M14))*MAX(0,15-T14+1)),0)))),0) | AF14: =IFERROR(IF(OR(R14<>"Yes",Q14<>"ESD"),0,IF(S14="Cash capital",IF(T14<=20,IF(O14<>"",O14,MAX(0,N(I14)+N(K14))*IF(N14<>"",N14,M14)),0),IF(S14="Debt service",IF(T14>20,0,W14*MAX(0,MIN(20-T14+1,U14))),IF(OR(S14="Annual O&M",S14="Maintenance-only"),IF(T14>20,0,IF(O14<>"",O14,MAX(0,N(I14)+N(K14))*IF(N14<>"",N14,M14))*MAX(0,20-T14+1)),0)))),0) | AG14: =IFERROR(IF(OR(R14<>"Yes",Q14<>"ESD"),0,IF(S14="Cash capital",IF(T14<=30,IF(O14<>"",O14,MAX(0,N(J14)+N(K14))*IF(N14<>"",N14,M14)),0),IF(S14="Debt service",IF(T14>30,0,W14*MAX(0,MIN(30-T14+1,U14))),IF(OR(S14="Annual O&M",S14="Maintenance-only"),IF(T14>30,0,IF(O14<>"",O14,MAX(0,N(J14)+N(K14))*IF(N14<>"",N14,M14))*MAX(0,30-T14+1)),0)))),0) | AH14: Planning benchmark; frontage/trail plans should override.
A15: Drainage / detention acreage | B15: City | C15: captured acres | D15: acres | E15: 0.10 ac/ac | F15: ='03_Multi_Horizon_Results'!$B$5*'12_Takeoff_Assumptions'!$B$25 | G15: ='03_Multi_Horizon_Results'!$C$5*'12_Takeoff_Assumptions'!$B$25 | H15: ='03_Multi_Horizon_Results'!$D$5*'12_Takeoff_Assumptions'!$B$25 | I15: ='03_Multi_Horizon_Results'!$E$5*'12_Takeoff_Assumptions'!$B$25 | J15: ='03_Multi_Horizon_Results'!$F$5*'12_Takeoff_Assumptions'!$B$25 | L15: =MAX(0,N(G15)+N(K15)) | M15: 150000 | P15: =IFERROR(IF(O15<>"",O15,L15*IF(N15<>"",N15,M15)),0) | Q15: City | R15: No | S15: Debt service | T15: 1 | U15: 20 | V15: 0.045 | W15: =IFERROR(IF(AND(R15="Yes",S15="Debt service",U15>0),IF(V15=0,P15/U15,P15*V15/(1-(1+V15)^(-U15))),0),0) | X15: =IFERROR(IF(OR(R15<>"Yes",Q15<>"City"),0,IF(S15="Cash capital",IF(T15<=5,IF(O15<>"",O15,MAX(0,N(F15)+N(K15))*IF(N15<>"",N15,M15)),0),IF(S15="Debt service",IF(T15>5,0,W15*MAX(0,MIN(5-T15+1,U15))),IF(OR(S15="Annual O&M",S15="Maintenance-only"),IF(T15>5,0,IF(O15<>"",O15,MAX(0,N(F15)+N(K15))*IF(N15<>"",N15,M15))*MAX(0,5-T15+1)),0)))),0) | Y15: =IFERROR(IF(OR(R15<>"Yes",Q15<>"City"),0,IF(S15="Cash capital",IF(T15<=10,IF(O15<>"",O15,MAX(0,N(G15)+N(K15))*IF(N15<>"",N15,M15)),0),IF(S15="Debt service",IF(T15>10,0,W15*MAX(0,MIN(10-T15+1,U15))),IF(OR(S15="Annual O&M",S15="Maintenance-only"),IF(T15>10,0,IF(O15<>"",O15,MAX(0,N(G15)+N(K15))*IF(N15<>"",N15,M15))*MAX(0,10-T15+1)),0)))),0) | Z15: =IFERROR(IF(OR(R15<>"Yes",Q15<>"City"),0,IF(S15="Cash capital",IF(T15<=15,IF(O15<>"",O15,MAX(0,N(H15)+N(K15))*IF(N15<>"",N15,M15)),0),IF(S15="Debt service",IF(T15>15,0,W15*MAX(0,MIN(15-T15+1,U15))),IF(OR(S15="Annual O&M",S15="Maintenance-only"),IF(T15>15,0,IF(O15<>"",O15,MAX(0,N(H15)+N(K15))*IF(N15<>"",N15,M15))*MAX(0,15-T15+1)),0)))),0) | AA15: =IFERROR(IF(OR(R15<>"Yes",Q15<>"City"),0,IF(S15="Cash capital",IF(T15<=20,IF(O15<>"",O15,MAX(0,N(I15)+N(K15))*IF(N15<>"",N15,M15)),0),IF(S15="Debt service",IF(T15>20,0,W15*MAX(0,MIN(20-T15+1,U15))),IF(OR(S15="Annual O&M",S15="Maintenance-only"),IF(T15>20,0,IF(O15<>"",O15,MAX(0,N(I15)+N(K15))*IF(N15<>"",N15,M15))*MAX(0,20-T15+1)),0)))),0) | AB15: =IFERROR(IF(OR(R15<>"Yes",Q15<>"City"),0,IF(S15="Cash capital",IF(T15<=30,IF(O15<>"",O15,MAX(0,N(J15)+N(K15))*IF(N15<>"",N15,M15)),0),IF(S15="Debt service",IF(T15>30,0,W15*MAX(0,MIN(30-T15+1,U15))),IF(OR(S15="Annual O&M",S15="Maintenance-only"),IF(T15>30,0,IF(O15<>"",O15,MAX(0,N(J15)+N(K15))*IF(N15<>"",N15,M15))*MAX(0,30-T15+1)),0)))),0) | AC15: =IFERROR(IF(OR(R15<>"Yes",Q15<>"ESD"),0,IF(S15="Cash capital",IF(T15<=5,IF(O15<>"",O15,MAX(0,N(F15)+N(K15))*IF(N15<>"",N15,M15)),0),IF(S15="Debt service",IF(T15>5,0,W15*MAX(0,MIN(5-T15+1,U15))),IF(OR(S15="Annual O&M",S15="Maintenance-only"),IF(T15>5,0,IF(O15<>"",O15,MAX(0,N(F15)+N(K15))*IF(N15<>"",N15,M15))*MAX(0,5-T15+1)),0)))),0) | AD15: =IFERROR(IF(OR(R15<>"Yes",Q15<>"ESD"),0,IF(S15="Cash capital",IF(T15<=10,IF(O15<>"",O15,MAX(0,N(G15)+N(K15))*IF(N15<>"",N15,M15)),0),IF(S15="Debt service",IF(T15>10,0,W15*MAX(0,MIN(10-T15+1,U15))),IF(OR(S15="Annual O&M",S15="Maintenance-only"),IF(T15>10,0,IF(O15<>"",O15,MAX(0,N(G15)+N(K15))*IF(N15<>"",N15,M15))*MAX(0,10-T15+1)),0)))),0) | AE15: =IFERROR(IF(OR(R15<>"Yes",Q15<>"ESD"),0,IF(S15="Cash capital",IF(T15<=15,IF(O15<>"",O15,MAX(0,N(H15)+N(K15))*IF(N15<>"",N15,M15)),0),IF(S15="Debt service",IF(T15>15,0,W15*MAX(0,MIN(15-T15+1,U15))),IF(OR(S15="Annual O&M",S15="Maintenance-only"),IF(T15>15,0,IF(O15<>"",O15,MAX(0,N(H15)+N(K15))*IF(N15<>"",N15,M15))*MAX(0,15-T15+1)),0)))),0) | AF15: =IFERROR(IF(OR(R15<>"Yes",Q15<>"ESD"),0,IF(S15="Cash capital",IF(T15<=20,IF(O15<>"",O15,MAX(0,N(I15)+N(K15))*IF(N15<>"",N15,M15)),0),IF(S15="Debt service",IF(T15>20,0,W15*MAX(0,MIN(20-T15+1,U15))),IF(OR(S15="Annual O&M",S15="Maintenance-only"),IF(T15>20,0,IF(O15<>"",O15,MAX(0,N(I15)+N(K15))*IF(N15<>"",N15,M15))*MAX(0,20-T15+1)),0)))),0) | AG15: =IFERROR(IF(OR(R15<>"Yes",Q15<>"ESD"),0,IF(S15="Cash capital",IF(T15<=30,IF(O15<>"",O15,MAX(0,N(J15)+N(K15))*IF(N15<>"",N15,M15)),0),IF(S15="Debt service",IF(T15>30,0,W15*MAX(0,MIN(30-T15+1,U15))),IF(OR(S15="Annual O&M",S15="Maintenance-only"),IF(T15>30,0,IF(O15<>"",O15,MAX(0,N(J15)+N(K15))*IF(N15<>"",N15,M15))*MAX(0,30-T15+1)),0)))),0) | AH15: Drainage/detention planning share; drainage study should override.
